Workbook
Name Chris: _xlfn.ANCHORARRAY(LUT!$O$3)
Name ChrisTeam: _xlfn.ANCHORARRAY(LUT!$W$3)
Name CVP: LUT!$M$3:$M$9
Name HCType: LUT!$G$3:$G$6
Name Hugo: _xlfn.ANCHORARRAY(LUT!$P$3)
Name HugoTeam: _xlfn.ANCHORARRAY(LUT!$X$3)
Name Jeffrey: _xlfn.ANCHORARRAY(LUT!$U$3)
Name JeffreyTeam: _xlfn.ANCHORARRAY(LUT!$AC$3)
Name labour: LUT!$H$3:$H$26
Name Location: LUT!$I$3:$I$26
Name Matthias: _xlfn.ANCHORARRAY(LUT!$Q$3)
Name MatthiasTeam: _xlfn.ANCHORARRAY(LUT!$Y$3)
Name Rodney: LUT!$N$3
Name RodneyTeam: _xlfn.ANCHORARRAY(LUT!$V$3)
Name Scenarios: 'Ramp Scenarios'!$B$3:$B$11
Name Status: LUT!$J$3:$J$12
Name statusnote: LUT!$K$3:$K$12
Name Stephen: _xlfn.ANCHORARRAY(LUT!$R$3)
Name StephenTeam: _xlfn.ANCHORARRAY(LUT!$Z$3)
Name Syed: _xlfn.ANCHORARRAY(LUT!$S$3)
Name SyedTeam: _xlfn.ANCHORARRAY(LUT!$AA$3)
Name Terry: _xlfn.ANCHORARRAY(LUT!$T$3)
Name TerryTeam: _xlfn.ANCHORARRAY(LUT!$AB$3)

Sheet Assumptions (EPD)
A1: Instructions: Please enter your function's name and capture assumptions applicable to your sizing
A2: Team Name / Function | B2: Scope / Deliverables | C2: Assumptions | D2: Risks
A3: Platform Security FW | B3: 1. UBU /LibROM 2. ART FW / ASP FW / Manufacturing FW 3. Content Security: HDCP2.2 and WV | C3: For LibROM: 1. enabling of Eris / SEC3.5 features 2. If FIPS certification is required, embedded team will take over after AFE For Security FW: 1. ART FW / UBU / ASP FW / Manufacturing - enabling of exisiting features 2. No XSP 3. No change in HDCP feature comparing to previous/roadmap programs. No change in WV (WV will be based on amd vcn ip and not brighton, otherwise effort estimate will increase significantly) 4. PFO leads Content Protection (WV and HDCP) post-UU as it was done on KRK2e 5. FuSA and ASIL B by BU if any 6. The majority of the effort for UBU and LibROM is focused on the pre-silicon phase. There will be some follow-up work after bring-up, primarily for full validation of features at the SoC level, as well as potential ROM patches or LibROM overlay deliveries to address ROM issues or work around RTL-related issues.
A4: SPG_MM_Audio | B4: Scope of Work: • Reuse of Medusa ACP 7.3a (AAF2.0 & Client Linux leverage) • Delta: o SW ASILB support:  Audio chimes  ACP monitored by safety island o HW ASRC: Need to confirm with program – WIP. Note: For the base support we can leverage deliverables to automotive. FUSA and ASRC are prilim right now, will adjust the HC in future based on the final mPRS and the scope of FUSA work. | C4: 1. SW ASILB & HW ASRC are required as per the priliminary understanding. 2. Legacy reuse
A5: 3D Graphics and Compiler Team | C5: Assumptions: 1. We're moving forward with Open Sourced XGL & OGLP, which under Jeff W's organization instead of under Rodney's organization. 2. We're running this product on Linux & RTOS, no windows support for this program Therefore, there's no PAL work, no Graphics Compiler work, nor there is proprietary XGL & OGL work
A7: SPG_Display NPI | B7: Scope of Work (Linux Only): 1. Pre-Si + Post-Si baseline + DQE + CI 2. VPE based virtual HW plane (Dedicated VPE engine for virtual HW plane solution. Not support video processing (AT) use cases via VPE) | C7: 1. Virtual HW plane data path protection sizing is based on the proposed solution from DCN HW team. Need to rescope if the solution changes
A8: SPG_MM_Video NPI | B8: Leverage NVE version, that was bring up on Windows, is reused. NVE 1.3 will be used for Capitola. Capitola is the first to use this 1 core config of NVE NVE 1.3 FW and MMCore support for Linux upstream. Feature set scope is below: . HEVC / AVC / AV1 4:2:0 encode and decode . AV2 4:2:0 decode TBD . H.264 / H.265 4:2:2 encode and decode . H.264 / H.265 / AV2 4:4:4 encode and decode . Encode: Single-core, 4K-only . Decode: Single-core, 4K-only . No DCTD (no DNx decode) . No JPEG decode . No VPP . No MEE_ML . No MEE_Video | C8: 1. Linux only 2. No RAS/ASILB for NVE
A9: SPG_MM Video NTI | B9: UES feature validation, bringup/debug support UES ASILB support for functinal safety | C9: QoS policies is transparant to MM in the new internal VPE->DCN pipeline
A10: RLC Firmware | B10: Leverage Grimlock, Eris. | C10: Feature set for Capitola is not currently known. Sizing assumes significant deltas from Grimlock and Eris. New RLC FW required and program validation support. Post SI support will be transitioned to BU at AFE.
A11: CP Firmware | B11: Based on Grimlock | C11: Minor updates. Support for debug and bringup. Post SI support will be transitioned to BU at AFE.
A12: PMFW | B12: Leverage Medusa, Eric, Grimlock | C12: Pre-si development only. Post-si work is executed by the business unit.
A13: Core Linux | B13: Linux Bringup & Pre-Si Emulation: - Pre-SI Emulation - Pre-SI Linux Bringup - Linux Bringup (Silicon) with Base kernel Graphics API : - Mesa, OpenGL 4.6, OpenGL ES 3.2, Vulkan-1.4 (Baremetal issue debug) Kernel support: - Kernel Consultation support | C13: Graphics : - OpenGL SC is deprecated and is explicitly out of scope. - There is no clarity from the program side on the VulkanSC requirement. No sizing has been done until we get the clarity. Kernel : - Kernel related consultation. | D13: Does VulkanSC needs the GPU driver to be safety complaint ? Any new work w.r.t VulkanSC needs rescoping.
A14: Advanced Technologies Group | B14: -Program Management: Manage Capitola board delivery, Linux dependencies, Android bringup, xTS resolution -Architecture: Architecture support and technical guidance for Capitola platform - GNPU: Graphics performance analysis and ML workload analysis/optimization - Android VAS3.0: Deliver Android Automotive features -Robotics SW/Usecases: Deliver Robotics SW stack and end-customer use-cases including simulator HW acceleration - FuSA: ISO26262 functional safety guidance for ASIL-B compliance - DevOps + Validation/QA: Platform validation and quality assurance, CI build pipeline setup and maintenance | C14: - HC sizing is based on analogous programs (Fairview, Glacier Peak, GLK) since specific use-cases aren't yet available - Component teams own UMD, Compiler, and KMD delivery - Component teams own FuSa ASIL-level scoping/sizing for their modules. ATG scoping constrained to guidance/consulting only - Balanced ownership of full system validation split between ATG and other teams | D14: -Pre‑silicon VAS3.0 stack non-availability will delay Android bring‑up -Unclear validation ownership across teams -HC sizing uncertainty due to limited use‑case definition -Dependency risk from component team deliverables
A15: SPG_SPIO | B15: Leverage Medusa, Eris, Grimlock, Krackan - MPIO, MPDACC, OpenSIL, ESID, PFQ | C15: `- XGBE is leveraged from KRK, new PHY integration - Eris is baseline for other components - Fusa aspects not in scope / no impact to these components - Leverage Eris MEM PHY with 48b + Single Row Support - PCIE IDE support is new addition to Eris - Minimal support (consultation only) after bringup (focus on Build Infrastructure, MEM and MPIO)
A16: Pre-Si FW Prg Mgr | B16: FW program execution (HLD → AFE) by owning integrated plans, dependency mapping (FW, emulation, SimNow, DV), risk identification/closure, and executive readiness reporting to ensure feature enablement and milestone exit criteria are met across all pre-silicon workstreams | D16: Pre-Si execution is gated by alignment of models, validation, requirements, and cross-functional dependencies—any slip directly blocks FW readiness and milestone exits.
A17: PMFW | B17: Leverage Medusa, Eric, Grimlock | C17: Pre-si development only. Post-si work is executed by the business unit.

Sheet Capitola C40 v1.0 r2 (EPD)
A1: =_xlfn.XLOOKUP(AN2,Status,statusnote,"",0,1) -> Sizing is OPEN. Please UPDATE your estimates for your teams in this sheet. Also UPDATE the scope, assumptions and risks in the Assumptions tab. | AN1: Status
A2: {=MID(CELL("filename",A1),FIND("]",CELL("filename",A1))+1,256)} -> Capitola C40 v1.0 r2 (EPD) | D2: Notes: BU - AECG - incorporate the updated R&R scope work-split with EPD and G&E SW | AN2: In Progress
A3: Last Updated | C3: 46195 | D3: Schedule Milestones>> | L3: LSA | M3: LSB | N3: LSC | O3: LSD | P3: BTO | Q3: UU | V3: IP
D4: Resource Allocation | H4: 2026 | L4: =H4+1 -> 2027 | P4: =L4+1 -> 2028 | T4: =P4+1 -> 2029 | X4: =T4+1 -> 2030 | AB4: =X4+1 -> 2031 | AF4: =AB4+1 -> 2032 | AJ4: =SUBTOTAL(9,AJ6:AJ65) -> 15.1 | AK4: =SUBTOTAL(9,AK6:AK65) -> 4 | AL4: =AVERAGE(AL6:AL65) -> 12978.675 | AM4: =SUBTOTAL(9,AM6:AM65) -> 455087.57
A5: Category | B5: Leader | C5: Top Level Team | D5: Function / Contact | E5: Location | F5: Allocation File | G5: HC Type | H5: ="Q1"&RIGHT(H4,2) -> Q126 | I5: ="Q"&MID(H5,2,1)+1&RIGHT(H4,2) -> Q226 | J5: ="Q"&MID(I5,2,1)+1&RIGHT(H4,2) -> Q326 | K5: ="Q"&MID(J5,2,1)+1&RIGHT(H4,2) -> Q426 | L5: ="Q1"&RIGHT(L4,2) -> Q127 | M5: ="Q"&MID(L5,2,1)+1&RIGHT(L4,2) -> Q227 | N5: ="Q"&MID(M5,2,1)+1&RIGHT(L4,2) -> Q327 | O5: ="Q"&MID(N5,2,1)+1&RIGHT(L4,2) -> Q427 | P5: ="Q1"&RIGHT(P4,2) -> Q128 | Q5: ="Q"&MID(P5,2,1)+1&RIGHT(P4,2) -> Q228 | R5: ="Q"&MID(Q5,2,1)+1&RIGHT(P4,2) -> Q328 | S5: ="Q"&MID(R5,2,1)+1&RIGHT(P4,2) -> Q428 | T5: ="Q1"&RIGHT(T4,2) -> Q129 | U5: ="Q"&MID(T5,2,1)+1&RIGHT(T4,2) -> Q229 | V5: ="Q"&MID(U5,2,1)+1&RIGHT(T4,2) -> Q329 | W5: ="Q"&MID(V5,2,1)+1&RIGHT(T4,2) -> Q429 | X5: ="Q1"&RIGHT(X4,2) -> Q130 | Y5: ="Q"&MID(X5,2,1)+1&RIGHT(X4,2) -> Q230 | Z5: ="Q"&MID(Y5,2,1)+1&RIGHT(X4,2) -> Q330 | AA5: ="Q"&MID(Z5,2,1)+1&RIGHT(X4,2) -> Q430 | AB5: ="Q1"&RIGHT(AB4,2) -> Q131 | AC5: ="Q"&MID(AB5,2,1)+1&RIGHT(AB4,2) -> Q231 | AD5: ="Q"&MID(AC5,2,1)+1&RIGHT(AB4,2) -> Q331 | AE5: ="Q"&MID(AD5,2,1)+1&RIGHT(AB4,2) -> Q431 | AF5: ="Q1"&RIGHT(AF4,2) -> Q132 | AG5: ="Q"&MID(AF5,2,1)+1&RIGHT(AF4,2) -> Q232 | AH5: ="Q"&MID(AG5,2,1)+1&RIGHT(AF4,2) -> Q332 | AI5: ="Q"&MID(AH5,2,1)+1&RIGHT(AF4,2) -> Q432 | AJ5: Sum HC | AK5: Peak HC | AL5: Rate | AM5: Cost | AN5: HC Profile (mini) | AO5: Check
A6: {=IFERROR(IF(AM6>0,IF(_xlfn.XLOOKUP(F6,INDIRECT(B6),INDIRECT(B6),"NO")="NO","",_xlfn.XLOOKUP($C6,LUT!$B$3:$B$200,LUT!$D$3:$D$200,"")&""),""),"")} -> PFO | B6: Chris | C6: SPG_FWProgMgmt | D6: Pre-Si Sys FW PM | E6: Canada | F6: alloc_PFO_PM_Arch | G6: Incremental - XCHG | J6: 0.75 | K6: 1 | L6: 1 | M6: 1 | N6: 1 | O6: 1 | P6: 1 | Q6: 1 | R6: 0.75 | AJ6: =SUM(H6:AI6) -> 8.5 | AK6: =MAX(H6:AI6) -> 1 | AL6: =_xlfn.XLOOKUP(E6,Location,labour,0) -> 30138.25 | AM6: =AL6*AJ6 -> 256175.12
A7: {=IFERROR(IF(AM7>0,IF(_xlfn.XLOOKUP(F7,INDIRECT(B7),INDIRECT(B7),"NO")="NO","",_xlfn.XLOOKUP($C7,LUT!$B$3:$B$200,LUT!$D$3:$D$200,"")&""),""),"")} -> PFO | B7: Chris | C7: SPG_Platform Security | D7: UBU / LibROM | E7: Canada | F7: alloc_PSPSecurity_MKM | G7: Incremental - XCHG | L7: 1 | M7: 1 | N7: 1.5 | O7: 1.5 | P7: 1 | Q7: 1 | R7: 1 | AJ7: =SUM(H7:AI7) -> 8 | AK7: =MAX(H7:AI7) -> 1.5 | AL7: =_xlfn.XLOOKUP(E7,Location,labour,0) -> 30138.25 | AM7: =AL7*AJ7 -> 241106
A8: {=IFERROR(IF(AM8>0,IF(_xlfn.XLOOKUP(F8,INDIRECT(B8),INDIRECT(B8),"NO")="NO","",_xlfn.XLOOKUP($C8,LUT!$B$3:$B$200,LUT!$D$3:$D$200,"")&""),""),"")} -> PFO | B8: Chris | C8: SPG_Platform Security | D8: ART FW / ASP FW / Manufacturing FW | E8: Canada | F8: alloc_PSPSecurity_MKM | G8: Incremental - XCHG | L8: 1 | M8: 2 | N8: 2 | O8: 2 | P8: 2 | Q8: 2 | AJ8: =SUM(H8:AI8) -> 11 | AK8: =MAX(H8:AI8) -> 2 | AL8: =_xlfn.XLOOKUP(E8,Location,labour,0) -> 30138.25 | AM8: =AL8*AJ8 -> 331520.74 | AO8: =IF($AM8>0,IF(AND($G8<>"",$F8<>"",$A8<>"",$B8<>"",$C8<>""),"","Check"),"")
A9: {=IFERROR(IF(AM9>0,IF(_xlfn.XLOOKUP(F9,INDIRECT(B9),INDIRECT(B9),"NO")="NO","",_xlfn.XLOOKUP($C9,LUT!$B$3:$B$200,LUT!$D$3:$D$200,"")&""),""),"")} -> PFO | B9: Chris | C9: SPG_Platform Security | D9: Content Security (WV/HDCP) | E9: Canada | F9: alloc_PSPSecurity_MKM | G9: Incremental - XCHG | M9: 1 | N9: 1 | O9: 2 | P9: 2 | Q9: 2.5 | R9: 2.5 | S9: 2.5 | T9: 2.5 | U9: 2 | V9: 1 | W9: 0.5 | AJ9: =SUM(H9:AI9) -> 19.5 | AK9: =MAX(H9:AI9) -> 2.5 | AL9: =_xlfn.XLOOKUP(E9,Location,labour,0) -> 30138.25 | AM9: =AL9*AJ9 -> 587695.87
A10: {=IFERROR(IF(AM10>0,IF(_xlfn.XLOOKUP(F10,INDIRECT(B10),INDIRECT(B10),"NO")="NO","",_xlfn.XLOOKUP($C10,LUT!$B$3:$B$200,LUT!$D$3:$D$200,"")&""),""),"")} -> PFO | B10: Chris | C10: SPG_PMFW | D10: PMFW | E10: Canada | F10: alloc_PMFW | G10: Incremental - XCHG | M10: 2 | N10: 2 | O10: 2 | P10: 2 | Q10: 2 | R10: 1 | AJ10: =SUM(H10:AI10) -> 11 | AK10: =MAX(H10:AI10) -> 2 | AL10: =_xlfn.XLOOKUP(E10,Location,labour,0) -> 30138.25 | AM10: =AL10*AJ10 -> 331520.74 | AO10: =IF($AM10>0,IF(AND($G10<>"",$F10<>"",$A10<>"",$B10<>"",$C10<>""),"","Check"),"")
A11: {=IFERROR(IF(AM11>0,IF(_xlfn.XLOOKUP(F11,INDIRECT(B11),INDIRECT(B11),"NO")="NO","",_xlfn.XLOOKUP($C11,LUT!$B$3:$B$200,LUT!$D$3:$D$200,"")&""),""),"")} -> PFO | B11: Chris | C11: SPG_SPIO | D11: ICTFW | E11: Canada | F11: alloc_SPIO | G11: Incremental - XCHG | L11: 1.5 | M11: 3 | N11: 3 | O11: 3 | P11: 3 | Q11: 3 | R11: 0.5 | S11: 0.5 | T11: 0 | AJ11: =SUM(H11:AI11) -> 17.5 | AK11: =MAX(H11:AI11) -> 3 | AL11: =_xlfn.XLOOKUP(E11,Location,labour,0) -> 30138.25 | AM11: =AL11*AJ11 -> 527419.37
A12: {=IFERROR(IF(AM12>0,IF(_xlfn.XLOOKUP(F12,INDIRECT(B12),INDIRECT(B12),"NO")="NO","",_xlfn.XLOOKUP($C12,LUT!$B$3:$B$200,LUT!$D$3:$D$200,"")&""),""),"")} -> PFO | B12: Chris | C12: SPG_SPIO | D12: OpenSIL + PFQ | E12: Canada | F12: alloc_SPIO | G12: Incremental - XCHG | L12: 2 | M12: 2 | N12: 2 | O12: 2 | P12: 2 | Q12: 2 | R12: 1 | S12: 1 | AJ12: =SUM(H12:AI12) -> 14 | AK12: =MAX(H12:AI12) -> 2 | AL12: =_xlfn.XLOOKUP(E12,Location,labour,0) -> 30138.25 | AM12: =AL12*AJ12 -> 421935.49
A13: {=IFERROR(IF(AM13>0,IF(_xlfn.XLOOKUP(F13,INDIRECT(B13),INDIRECT(B13),"NO")="NO","",_xlfn.XLOOKUP($C13,LUT!$B$3:$B$200,LUT!$D$3:$D$200,"")&""),""),"")} -> PFO | B13: Chris | C13: SPG_SPIO | D13: MEM + DF | E13: Canada | F13: alloc_SPIO | G13: Incremental - XCHG | L13: 3 | M13: 3 | N13: 3 | O13: 3 | P13: 3 | Q13: 3 | R13: 0.5 | S13: 0.5 | AJ13: =SUM(H13:AI13) -> 19 | AK13: =MAX(H13:AI13) -> 3 | AL13: =_xlfn.XLOOKUP(E13,Location,labour,0) -> 30138.25 | AM13: =AL13*AJ13 -> 572626.74
A14: {=IFERROR(IF(AM14>0,IF(_xlfn.XLOOKUP(F14,INDIRECT(B14),INDIRECT(B14),"NO")="NO","",_xlfn.XLOOKUP($C14,LUT!$B$3:$B$200,LUT!$D$3:$D$200,"")&""),""),"")} -> PFO | B14: Chris | C14: SPG_VBIOS CP | D14: GAIT CP FW | E14: Canada | F14: alloc_CP | G14: Incremental - XCHG | L14: 1 | M14: 1 | N14: 1 | O14: 1 | P14: 1 | Q14: 1 | R14: 1 | S14: 1 | AJ14: =SUM(H14:AI14) -> 8 | AK14: =MAX(H14:AI14) -> 1 | AL14: =_xlfn.XLOOKUP(E14,Location,labour,0) -> 30138.25 | AM14: =AL14*AJ14 -> 241106 | AO14: =IF($AM14>0,IF(AND($G14<>"",$F14<>"",$A14<>"",$B14<>"",$C14<>""),"","Check"),"")
A15: PFO | B15: Chris | C15: SPG_VBIOS RLC | D15: GAIT RLC FW | E15: USA | F15: alloc_RLC | G15: Existing FTE | J15: 2 | K15: 2 | L15: 2 | M15: 2 | N15: 2 | O15: 2 | P15: 2 | Q15: 2 | R15: 2 | S15: 2 | T15: 2 | U15: 2 | V15: 2
A16: {=IFERROR(IF(AM16>0,IF(_xlfn.XLOOKUP(F16,INDIRECT(B16),INDIRECT(B16),"NO")="NO","",_xlfn.XLOOKUP($C16,LUT!$B$3:$B$200,LUT!$D$3:$D$200,"")&""),""),"")} -> PFO | B16: Chris | C16: SPG_VBIOS RLC | D16: GAIT RLC FW | E16: China Shanghai | F16: alloc_RLC | G16: Incremental - XCHG | J16: 1 | K16: 1 | L16: 1 | M16: 1 | N16: 1 | O16: 1 | P16: 1 | Q16: 1 | R16: 1 | S16: 1 | T16: 1 | U16: 1 | V16: 1 | AJ16: =SUM(H16:AI16) -> 13 | AK16: =MAX(H16:AI16) -> 1 | AL16: =_xlfn.XLOOKUP(E16,Location,labour,0) -> 27275.209 | AM16: =AL16*AJ16 -> 354577.71
A17: {=IFERROR(IF(AM17>0,IF(_xlfn.XLOOKUP(F17,INDIRECT(B17),INDIRECT(B17),"NO")="NO","",_xlfn.XLOOKUP($C17,LUT!$B$3:$B$200,LUT!$D$3:$D$200,"")&""),""),"")} -> Security | B17: Hugo | C17: SPG_Security | D17: SDL | E17: USA | F17: alloc_Product Security | G17: Existing - AOP | K17: 0.1 | L17: 0.1 | M17: 0.2 | N17: 0.2 | O17: 0.2 | P17: 0.2 | Q17: 0.2 | R17: 0.2 | S17: 0.1 | T17: 0.1 | U17: 0.1 | V17: 0.1 | AJ17: =SUM(H17:AI17) -> 1.8 | AK17: =MAX(H17:AI17) -> 0.2 | AL17: =_xlfn.XLOOKUP(E17,Location,labour,0) -> 57001.202 | AM17: =AL17*AJ17 -> 102602.16 | AO17: =IF($AM17>0,IF(AND($G17<>"",$F17<>"",$A17<>"",$B17<>"",$C17<>""),"","Check"),"")
A18: {=IFERROR(IF(AM18>0,IF(_xlfn.XLOOKUP(F18,INDIRECT(B18),INDIRECT(B18),"NO")="NO","",_xlfn.XLOOKUP($C18,LUT!$B$3:$B$200,LUT!$D$3:$D$200,"")&""),""),"")} -> Security | B18: Hugo | C18: SPG_Security | D18: FIPS certification | E18: USA | F18: alloc_Product Security | G18: Existing - AOP | L18: 0.1 | M18: 0.2 | N18: 0.2 | O18: 0.2 | P18: 0.2 | Q18: 0.2 | R18: 0.2 | S18: 0.1 | T18: 0.1 | U18: 0.1 | V18: 0.1 | AJ18: =SUM(H18:AI18) -> 1.7 | AK18: =MAX(H18:AI18) -> 0.2 | AL18: =_xlfn.XLOOKUP(E18,Location,labour,0) -> 57001.202 | AM18: =AL18*AJ18 -> 96902.043 | AO18: =IF($AM18>0,IF(AND($G18<>"",$F18<>"",$A18<>"",$B18<>"",$C18<>""),"","Check"),"")
A19: {=IFERROR(IF(AM19>0,IF(_xlfn.XLOOKUP(F19,INDIRECT(B19),INDIRECT(B19),"NO")="NO","",_xlfn.XLOOKUP($C19,LUT!$B$3:$B$200,LUT!$D$3:$D$200,"")&""),""),"")} -> SW PM | B19: Matthias | C19: SPG_SW_ProgramManagers | D19: Cross-Functional SW PM | E19: Canada | F19: alloc_Program Management_AlejandroR | G19: Existing - AOP | I19: 0.1 | J19: 0.2 | K19: 0.3 | L19: 0.5 | M19: 0.5 | N19: 0.5 | O19: 0.5 | P19: 0.5 | Q19: 0.5 | R19: 0.5 | S19: 0.5 | T19: 0.5 | U19: 0.5 | V19: 0.3 | W19: 0.2 | AD19: 0 | AE19: 0 | AJ19: =SUM(H19:AI19) -> 6.1 | AK19: =MAX(H19:AI19) -> 0.5 | AL19: =_xlfn.XLOOKUP(E19,Location,labour,0) -> 30138.25 | AM19: =AL19*AJ19 -> 183843.32 | AO19: =IF($AM19>0,IF(AND($G19<>"",$F19<>"",$A19<>"",$B19<>"",$C19<>""),"","Check"),"")
A20: {=IFERROR(IF(AM20>0,IF(_xlfn.XLOOKUP(F20,INDIRECT(B20),INDIRECT(B20),"NO")="NO","",_xlfn.XLOOKUP($C20,LUT!$B$3:$B$200,LUT!$D$3:$D$200,"")&""),""),"")} -> 3DGFX | B20: Rodney | C20: SPG_ShaderCompiler | D20: Lightning Compiler | E20: USA | F20: alloc_CG 3D Drivers And Compilers | G20: Existing - AOP | K20: 1 | L20: 1 | M20: 1 | N20: 1 | O20: 1 | P20: 1 | Q20: 1 | R20: 1 | S20: 1 | T20: 1 | U20: 1 | AJ20: =SUM(H20:AI20) -> 11 | AK20: =MAX(H20:AI20) -> 1 | AL20: =_xlfn.XLOOKUP(E20,Location,labour,0) -> 57001.202 | AM20: =AL20*AJ20 -> 627013.22
A21: {=IFERROR(IF(AM21>0,IF(_xlfn.XLOOKUP(F21,INDIRECT(B21),INDIRECT(B21),"NO")="NO","",_xlfn.XLOOKUP($C21,LUT!$B$3:$B$200,LUT!$D$3:$D$200,"")&""),""),"")} -> Disp&MM | B21: Syed | C21: SPG_Display NPI | D21: Charlie Wang | E21: Canada | F21: alloc_Display Solution_CharlieW | G21: Incremental - XCHG | K21: 0 | L21: 0 | M21: 1 | N21: 1 | O21: 2 | P21: 2 | Q21: 2 | R21: 3 | S21: 3 | T21: 3 | U21: 2 | V21: 2 | AJ21: =SUM(H21:AI21) -> 21 | AK21: =MAX(H21:AI21) -> 3 | AL21: =_xlfn.XLOOKUP(E21,Location,labour,0) -> 30138.25 | AM21: =AL21*AJ21 -> 632903.24
A22: {=IFERROR(IF(AM22>0,IF(_xlfn.XLOOKUP(F22,INDIRECT(B22),INDIRECT(B22),"NO")="NO","",_xlfn.XLOOKUP($C22,LUT!$B$3:$B$200,LUT!$D$3:$D$200,"")&""),""),"")} -> Disp&MM | B22: Syed | C22: SPG_Display NPI | D22: Michael Vasnetsov | E22: Canada | F22: alloc_Display Solution_MazenS | G22: Incremental - XCHG | L22: 1 | M22: 1 | N22: 1 | O22: 1 | P22: 2 | Q22: 2 | R22: 2 | S22: 1 | T22: 1 | U22: 1 | V22: 1 | AJ22: =SUM(H22:AI22) -> 14 | AK22: =MAX(H22:AI22) -> 2 | AL22: =_xlfn.XLOOKUP(E22,Location,labour,0) -> 30138.25 | AM22: =AL22*AJ22 -> 421935.49
A23: {=IFERROR(IF(AM23>0,IF(_xlfn.XLOOKUP(F23,INDIRECT(B23),INDIRECT(B23),"NO")="NO","",_xlfn.XLOOKUP($C23,LUT!$B$3:$B$200,LUT!$D$3:$D$200,"")&""),""),"")} -> Disp&MM | B23: Syed | C23: SPG_VPE & DisplayNTI | D23: Mazen Salloum | E23: Canada | F23: alloc_Display Solution_MazenS | G23: Incremental - XCHG | M23: 3 | N23: 3 | O23: 3 | P23: 3 | Q23: 3 | R23: 3 | S23: 3 | AJ23: =SUM(H23:AI23) -> 21 | AK23: =MAX(H23:AI23) -> 3 | AL23: =_xlfn.XLOOKUP(E23,Location,labour,0) -> 30138.25 | AM23: =AL23*AJ23 -> 632903.24
A24: {=IFERROR(IF(AM24>0,IF(_xlfn.XLOOKUP(F24,INDIRECT(B24),INDIRECT(B24),"NO")="NO","",_xlfn.XLOOKUP($C24,LUT!$B$3:$B$200,LUT!$D$3:$D$200,"")&""),""),"")} -> Disp&MM | B24: Syed | C24: SPG_MM Audio | D24: ACP FW/ Driver | E24: Taiwan | F24: alloc_SWDEV_HYD_MM_Audio_NonWin | G24: Incremental - XCHG | L24: 2 | M24: 2 | N24: 2 | O24: 3 | P24: 4 | Q24: 4 | R24: 3 | S24: 2 | T24: 1 | U24: 1 | V24: 0 | W24: 0 | AJ24: =SUM(H24:AI24) -> 24 | AK24: =MAX(H24:AI24) -> 4 | AL24: =_xlfn.XLOOKUP(E24,Location,labour,0) -> 24974.506 | AM24: =AL24*AJ24 -> 599388.15
A25: {=IFERROR(IF(AM25>0,IF(_xlfn.XLOOKUP(F25,INDIRECT(B25),INDIRECT(B25),"NO")="NO","",_xlfn.XLOOKUP($C25,LUT!$B$3:$B$200,LUT!$D$3:$D$200,"")&""),""),"")} -> Disp&MM | B25: Syed | C25: SPG_MM Video NPI | D25: Konstantin Moskvitin | E25: Canada | F25: alloc_mmdrivers_video_playback_pipelines | G25: Incremental - XCHG | M25: 0.5 | N25: 0.5 | O25: 1 | P25: 1 | Q25: 1 | R25: 1 | S25: 1 | T25: 1 | U25: 1 | V25: 1 | AJ25: =SUM(H25:AI25) -> 9 | AK25: =MAX(H25:AI25) -> 1 | AL25: =_xlfn.XLOOKUP(E25,Location,labour,0) -> 30138.25 | AM25: =AL25*AJ25 -> 271244.25 | AO25: =IF($AM25>0,IF(AND($G25<>"",$F25<>"",$A25<>"",$B25<>"",$C25<>""),"","Check"),"")
A26: {=IFERROR(IF(AM26>0,IF(_xlfn.XLOOKUP(F26,INDIRECT(B26),INDIRECT(B26),"NO")="NO","",_xlfn.XLOOKUP($C26,LUT!$B$3:$B$200,LUT!$D$3:$D$200,"")&""),""),"")} -> Disp&MM | B26: Syed | C26: SPG_MM Video NTI | D26: Bill Li | E26: Canada | F26: alloc_mmdrivers_video_encode | G26: Incremental - XCHG | K26: 1 | L26: 1 | M26: 1 | N26: 1 | O26: 1 | P26: 1 | Q26: 1.5 | R26: 1.5 | S26: 1.5 | T26: 1.5 | U26: 1 | V26: 1 | AJ26: =SUM(H26:AI26) -> 14 | AK26: =MAX(H26:AI26) -> 1.5 | AL26: =_xlfn.XLOOKUP(E26,Location,labour,0) -> 30138.25 | AM26: =AL26*AJ26 -> 421935.49
A27: {=IFERROR(IF(AM27>0,IF(_xlfn.XLOOKUP(F27,INDIRECT(B27),INDIRECT(B27),"NO")="NO","",_xlfn.XLOOKUP($C27,LUT!$B$3:$B$200,LUT!$D$3:$D$200,"")&""),""),"")} -> PlatLinux | B27: Chris | C27: SPG_Platform_Linux | D27: PreSI emulation | E27: Canada | F27: alloc_MLS_Linux_4 | G27: Incremental - XCHG | O27: 1 | P27: 1 | Q27: 1.5 | R27: 0.5 | AJ27: =SUM(H27:AI27) -> 4 | AK27: =MAX(H27:AI27) -> 1.5 | AL27: =_xlfn.XLOOKUP(E27,Location,labour,0) -> 30138.25 | AM27: =AL27*AJ27 -> 120553 | AO27: =IF($AM27>0,IF(AND($G27<>"",$F27<>"",$A27<>"",$B27<>"",$C27<>""),"","Check"),"")
A28: {=IFERROR(IF(AM28>0,IF(_xlfn.XLOOKUP(F28,INDIRECT(B28),INDIRECT(B28),"NO")="NO","",_xlfn.XLOOKUP($C28,LUT!$B$3:$B$200,LUT!$D$3:$D$200,"")&""),""),"")} -> PlatLinux | B28: Chris | C28: SPG_Platform_Linux | D28: NPI support(Linux Bringup (Silicon) with Base kernel) | E28: Canada | F28: alloc_MLS_Linux_4 | G28: Incremental - XCHG | P28: 0.5 | Q28: 1 | R28: 2 | S28: 1.5 | T28: 1.5 | U28: 0.5 | AJ28: =SUM(H28:AI28) -> 7 | AK28: =MAX(H28:AI28) -> 2 | AL28: =_xlfn.XLOOKUP(E28,Location,labour,0) -> 30138.25 | AM28: =AL28*AJ28 -> 210967.75 | AO28: =IF($AM28>0,IF(AND($G28<>"",$F28<>"",$A28<>"",$B28<>"",$C28<>""),"","Check"),"")
A29: {=IFERROR(IF(AM29>0,IF(_xlfn.XLOOKUP(F29,INDIRECT(B29),INDIRECT(B29),"NO")="NO","",_xlfn.XLOOKUP($C29,LUT!$B$3:$B$200,LUT!$D$3:$D$200,"")&""),""),"")} -> PlatLinux | B29: Chris | C29: SPG_Platform_Linux | D29: - Mesa, OpenGL 4.6, OpenGL ES 3.2, Vulkan-1.4 (Baremetal issue debug) | E29: Canada | F29: alloc_MLS_Linux_4 | G29: Incremental - XCHG | P29: 0.5 | Q29: 0.5 | R29: 0.5 | S29: 0.5 | T29: 0.5 | U29: 0.5 | V29: 0.5 | W29: 0.3 | X29: 0.3 | AJ29: =SUM(H29:AI29) -> 4.1 | AK29: =MAX(H29:AI29) -> 0.5 | AL29: =_xlfn.XLOOKUP(E29,Location,labour,0) -> 30138.25 | AM29: =AL29*AJ29 -> 123566.82 | AO29: =IF($AM29>0,IF(AND($G29<>"",$F29<>"",$A29<>"",$B29<>"",$C29<>""),"","Check"),"")
AJ30: =SUM(H30:AI30) -> 0 | AK30: =MAX(H30:AI30) -> 0 | AL30: =_xlfn.XLOOKUP(E30,Location,labour,0) -> 0 | AM30: =AL30*AJ30 -> 0
A31: {=IFERROR(IF(AM31>0,IF(_xlfn.XLOOKUP(F31,INDIRECT(B31),INDIRECT(B31),"NO")="NO","",_xlfn.XLOOKUP($C31,LUT!$B$3:$B$200,LUT!$D$3:$D$200,"")&""),""),"")} | AJ31: =SUM(H31:AI31) -> 0 | AK31: =MAX(H31:AI31) -> 0 | AL31: =_xlfn.XLOOKUP(E31,Location,labour,0) -> 0 | AM31: =AL31*AJ31 -> 0
A32: {=IFERROR(IF(AM32>0,IF(_xlfn.XLOOKUP(F32,INDIRECT(B32),INDIRECT(B32),"NO")="NO","",_xlfn.XLOOKUP($C32,LUT!$B$3:$B$200,LUT!$D$3:$D$200,"")&""),""),"")} | AJ32: =SUM(H32:AI32) -> 0 | AK32: =MAX(H32:AI32) -> 0 | AL32: =_xlfn.XLOOKUP(E32,Location,labour,0) -> 0 | AM32: =AL32*AJ32 -> 0
A33: {=IFERROR(IF(AM33>0,IF(_xlfn.XLOOKUP(F33,INDIRECT(B33),INDIRECT(B33),"NO")="NO","",_xlfn.XLOOKUP($C33,LUT!$B$3:$B$200,LUT!$D$3:$D$200,"")&""),""),"")} | AJ33: =SUM(H33:AI33) -> 0 | AK33: =MAX(H33:AI33) -> 0 | AL33: =_xlfn.XLOOKUP(E33,Location,labour,0) -> 0 | AM33: =AL33*AJ33 -> 0
A34: {=IFERROR(IF(AM34>0,IF(_xlfn.XLOOKUP(F34,INDIRECT(B34),INDIRECT(B34),"NO")="NO","",_xlfn.XLOOKUP($C34,LUT!$B$3:$B$200,LUT!$D$3:$D$200,"")&""),""),"")} | AJ34: =SUM(H34:AI34) -> 0 | AK34: =MAX(H34:AI34) -> 0 | AL34: =_xlfn.XLOOKUP(E34,Location,labour,0) -> 0 | AM34: =AL34*AJ34 -> 0
A35: {=IFERROR(IF(AM35>0,IF(_xlfn.XLOOKUP(F35,INDIRECT(B35),INDIRECT(B35),"NO")="NO","",_xlfn.XLOOKUP($C35,LUT!$B$3:$B$200,LUT!$D$3:$D$200,"")&""),""),"")} | AJ35: =SUM(H35:AI35) -> 0 | AK35: =MAX(H35:AI35) -> 0 | AL35: =_xlfn.XLOOKUP(E35,Location,labour,0) -> 0 | AM35: =AL35*AJ35 -> 0 | AO35: =IF($AM35>0,IF(AND($G35<>"",$F35<>"",$A35<>"",$B35<>"",$C35<>""),"","Check"),"")
A36: {=IFERROR(IF(AM36>0,IF(_xlfn.XLOOKUP(F36,INDIRECT(B36),INDIRECT(B36),"NO")="NO","",_xlfn.XLOOKUP($C36,LUT!$B$3:$B$200,LUT!$D$3:$D$200,"")&""),""),"")} | AJ36: =SUM(H36:AI36) -> 0 | AK36: =MAX(H36:AI36) -> 0 | AL36: =_xlfn.XLOOKUP(E36,Location,labour,0) -> 0 | AM36: =AL36*AJ36 -> 0 | AO36: =IF($AM36>0,IF(AND($G36<>"",$F36<>"",$A36<>"",$B36<>"",$C36<>""),"","Check"),"")
A37: {=IFERROR(IF(AM37>0,IF(_xlfn.XLOOKUP(F37,INDIRECT(B37),INDIRECT(B37),"NO")="NO","",_xlfn.XLOOKUP($C37,LUT!$B$3:$B$200,LUT!$D$3:$D$200,"")&""),""),"")} | AJ37: =SUM(H37:AI37) -> 0 | AK37: =MAX(H37:AI37) -> 0 | AL37: =_xlfn.XLOOKUP(E37,Location,labour,0) -> 0 | AM37: =AL37*AJ37 -> 0 | AO37: =IF($AM37>0,IF(AND($G37<>"",$F37<>"",$A37<>"",$B37<>"",$C37<>""),"","Check"),"")
A38: {=IFERROR(IF(AM38>0,IF(_xlfn.XLOOKUP(F38,INDIRECT(B38),INDIRECT(B38),"NO")="NO","",_xlfn.XLOOKUP($C38,LUT!$B$3:$B$200,LUT!$D$3:$D$200,"")&""),""),"")} | AJ38: =SUM(H38:AI38) -> 0 | AK38: =MAX(H38:AI38) -> 0 | AL38: =_xlfn.XLOOKUP(E38,Location,labour,0) -> 0 | AM38: =AL38*AJ38 -> 0 | AO38: =IF($AM38>0,IF(AND($G38<>"",$F38<>"",$A38<>"",$B38<>"",$C38<>""),"","Check"),"")
A39: {=IFERROR(IF(AM39>0,IF(_xlfn.XLOOKUP(F39,INDIRECT(B39),INDIRECT(B39),"NO")="NO","",_xlfn.XLOOKUP($C39,LUT!$B$3:$B$200,LUT!$D$3:$D$200,"")&""),""),"")} | AJ39: =SUM(H39:AI39) -> 0 | AK39: =MAX(H39:AI39) -> 0 | AL39: =_xlfn.XLOOKUP(E39,Location,labour,0) -> 0 | AM39: =AL39*AJ39 -> 0 | AO39: =IF($AM39>0,IF(AND($G39<>"",$F39<>"",$A39<>"",$B39<>"",$C39<>""),"","Check"),"")
A40: {=IFERROR(IF(AM40>0,IF(_xlfn.XLOOKUP(F40,INDIRECT(B40),INDIRECT(B40),"NO")="NO","",_xlfn.XLOOKUP($C40,LUT!$B$3:$B$200,LUT!$D$3:$D$200,"")&""),""),"")} | AJ40: =SUM(H40:AI40) -> 0 | AK40: =MAX(H40:AI40) -> 0 | AL40: =_xlfn.XLOOKUP(E40,Location,labour,0) -> 0 | AM40: =AL40*AJ40 -> 0 | AO40: =IF($AM40>0,IF(AND($G40<>"",$F40<>"",$A40<>"",$B40<>"",$C40<>""),"","Check"),"")
...

Sheet Assumptions (PAVS)
A1: Instructions: Please enter your function's name and capture assumptions applicable to your sizing
A2: Team Name / Function | B2: Scope / Deliverables | C2: Assumptions | D2: Risks
A3: Platform Security FW | B3: No PAVS Deliverables
A4: SPG_MM_Audio | B4: Scope of Work: • Reuse of Medusa ACP 7.3a (AAF2.0 & Client Linux leverage) • Delta: o SW ASILB support:  Audio chimes  ACP monitored by safety island o HW ASRC: Need to confirm with program – WIP. Note: For the base support we can leverage deliverables to automotive. FUSA and ASRC are prilim right now, will adjust the HC in future based on the final mPRS and the scope of FUSA work. | C4: 1. SW ASILB & HW ASRC are required as per the priliminary understanding. 2. Legacy reuse
A5: 3D Graphics and Compiler Team | C5: Assumptions: 1. We're moving forward with Open Sourced XGL & OGLP, which under Jeff W's organization instead of under Rodney's organization. 2. We're running this product on Linux & RTOS, no windows support for this program Therefore, there's no PAL work, no Graphics Compiler work, nor there is proprietary XGL & OGL work
A6: SPG_Display NPI | B6: Scope of Work (Linux Only): 1. RAS Features: . Virtual HW plane data path protection (based on the proposed solution from DCN HW team which need to be aligned with Embedded) . Increase ROI / pipe from 2 to 4 for DisplayCRC feature . Boot time display pipe stuck checking and reporting . Display pipe hang detection and reporting . Display data poison detection and reporting 2. DCN Linux kernel (within AMDGPU) and DCN FW for DCN RAS features are ASIL-B ready for certification (documentation, test coverage, coding standard) 3. (06/30) Added windows support leveraging common arch from linux with some delta work to power optimize video playback on windows | C6: 1. The sizing does not include FuSA certification effort with FuSA accessors such as TÜV, SGS as it's customer solution end-to-end based 2. For RAS features which will report stuck/hang/poison, the assumption is the system need to decide what corrective action is needed to recover the hang. VPE/DCN just performs the reporting 3. Assumes work being done by KMD to enable the power optimized windows solution (Specifically: work for plumbing calls from DM/DC to enable work submission to VPE for queue/ctx mgmt, cmd submission, create fences, monitor fences)
A7: SPG_MM_Video NPI | B7: Leverage NVE version, that was bring up on Windows, is reused. NVE 1.3 will be used for Capitola. Capitola is the first to use this 1 core config of NVE NVE 1.3 FW and MMCore support for Linux upstream. Feature set scope is below: . HEVC / AVC / AV1 4:2:0 encode and decode . AV2 4:2:0 decode TBD . H.264 / H.265 4:2:2 encode and decode . H.264 / H.265 / AV2 4:4:4 encode and decode . Encode: Single-core, 4K-only . Decode: Single-core, 4K-only . No DCTD (no DNx decode) . No JPEG decode . No VPP . No MEE_ML . No MEE_Video | C7: 1. Linux only 2. No RAS/ASILB for NVE
A8: SPG_MM Video NTI | B8: UES feature validation, bringup/debug support UES ASILB support for functinal safety | C8: QoS policies is transparant to MM in the new internal VPE->DCN pipeline
A9: RLC Firmware | B9: No PAVS Deliverables
A10: CP Firmware | B10: No PAVS Deliverables
A11: PMFW | B11: No PAVS Deliverables
A12: Core Linux | B12: ROCm Support: - ROCm bringup on APU - ROCm Feats validation - KFD validation MM: - H264 and HEVC(Encode, Decode and Transcode) issue debug support. - NVE support BPI : 1. Build and Packaging 2. Separate Capitola branch creation. 3. Build script modifications if any. Linux IQE - Feature validation for ROCm/GFX/Display/MM/tools/Xen/ML Frameworks with Linux OS - Weekly integration test - Full cycle release test Graphics Virtualization - Guest Linux GPU recovery virtualization VirtIO GPU emulation - Xen/QEMU/Virglrenderer DOM0 (Graphics) VirtIO GPU emulation - Xen/QEMU/Virglrenderer DOM0 (Graphics - Windows) Graphics Virtualization - Guest Windows UMD (Virgl) Display Virtualization Display Virtualization (Windows) Graphics Virtualization - Guest Windows KMD Compute Virtualization - Guest ROCm (virtio-gpu) Compute Virtualization - Guest OpenCL (DOMU) Compute Virtualization - Host KFD multiple context Compute Virtualization - Guest HIP & Mathlib & Tools (DOMU) VirtIO GPU emulation - Xen/QEMU/Virglrenderer DOM0 (Compute) Cross functional team support/ Integrated Delivery Support DRM render node for ROCm virtualization Power Management Virtualization - Guest Graphics Virtualization - Guest Android (Issue Debugging Support) Linux - Solution Architect team | C12: ROCm Support: - Validate the ROCm FEATs like KFD test, rocr test, roc profiler, roc gdb, rocminfo, clinfo, rocmruntime, OCL, etc MM: - Debug support is limited to H.264 and HEVC use cases, including Encode, Decode, and Transcode only. - VCN5 does not support YUV422 Subsampling format. So we don’t support this. - No new feature development is included as part of this scope. - GStreamer-based development or support is explicitly out of scope. - QT framework is out of scope. Linux IQE -Validation scope for ROCm stack is limited to KFD test/rocr test/rocprofiler/rocgdb/OCL - ML framework scope limited to Pytorch, Ollama.cpp, llama.cpp, vllm, NO performance validation -FuSa related features are out of this sizing scope -RAS validation is out of scope Linux: • Weston IVI is out of the scope. • Multidisplay is not scoped. • Dom0 and DomU should be in a display like Fairview Project. (One DOM0 + One DOMU in one single display). If requires more use cases, it need require CR. • Virtual primary plane is not scoped. • Functional safety (ASIL-B) for graphics driver and ROCm is not scoped. • P2P is not in scope. APU doesn’t support the P2P feature, so some IPC features cannot be enabled either. Windows: • Graphics Virtualization(UMD) → This phase provides a DirectX-10–based, GPU-accelerated Windows 10 desktop only. DX12, Windows 11, Vulkan, and Windows VM multimedia are explicitly out of scope. • No power management on Windows DOMU • Windows will not support vMPO/vPP, GPU timeout recovery. | D12: No ASIL-B or ASIL-D efforts are estimated till we get the clear picture of usage on the UMD/D4KMD or ROCm side.
A13: Advanced Technologies Group | B13: -Program Management: Manage Capitola board delivery, Linux dependencies, Android bringup, xTS resolution -Architecture: Architecture support and technical guidance for Capitola platform - GNPU: Graphics performance analysis and ML workload analysis/optimization - Android VAS3.0: Deliver Android Automotive features -Robotics SW/Usecases: Deliver Robotics SW stack and end-customer use-cases including simulator HW acceleration - FuSA: ISO26262 functional safety guidance for ASIL-B compliance - DevOps + Validation/QA: Platform validation and quality assurance, CI build pipeline setup and maintenance | C13: - HC sizing is based on analogous programs (Fairview, Glacier Peak, GLK) since specific use-cases aren't yet available - Component teams own UMD, Compiler, and KMD delivery - Component teams own FuSa ASIL-level scoping/sizing for their modules. ATG scoping constrained to guidance/consulting only - Balanced ownership of full system validation split between ATG and other teams | D13: -Pre‑silicon VAS3.0 stack non-availability will delay Android bring‑up -Unclear validation ownership across teams -HC sizing uncertainty due to limited use‑case definition -Dependency risk from component team deliverables
A14: SPG_SPIO | B14: No PAVS Deliverables
A15: Pre-Si FW Prg Mgr | B15: No PAVS Deliverables

Sheet Capitola C40 v1.0 r2 (PAVS)
A1: =_xlfn.XLOOKUP(AN2,Status,statusnote,"",0,1) -> Sizing is OPEN. Please UPDATE your estimates for your teams in this sheet. Also UPDATE the scope, assumptions and risks in the Assumptions tab. | AN1: Status
A2: {=MID(CELL("filename",A1),FIND("]",CELL("filename",A1))+1,256)} -> Capitola C40 v1.0 r2 (PAVS) | D2: Notes: BU - AECG - incorporate the updated R&R scope work-split with PAVS and G&E SW | AN2: In Progress
A3: Last Updated | C3: 46195 | D3: Schedule Milestones>> | L3: LSA | M3: LSB | N3: LSC | O3: LSD | P3: BTO | Q3: UU | V3: IP
D4: Resource Allocation | H4: 2026 | L4: =H4+1 -> 2027 | P4: =L4+1 -> 2028 | T4: =P4+1 -> 2029 | X4: =T4+1 -> 2030 | AB4: =X4+1 -> 2031 | AF4: =AB4+1 -> 2032 | AJ4: =SUBTOTAL(9,AJ6:AJ59) -> 170.5 | AK4: =SUBTOTAL(9,AK6:AK59) -> 24 | AL4: =AVERAGE(AL6:AL59) -> 10286.083 | AM4: =SUBTOTAL(9,AM6:AM59) -> 4724862.2
A5: Category | B5: Leader | C5: Top Level Team | D5: Function / Contact | E5: Location | F5: Allocation File | G5: HC Type | H5: ="Q1"&RIGHT(H4,2) -> Q126 | I5: ="Q"&MID(H5,2,1)+1&RIGHT(H4,2) -> Q226 | J5: ="Q"&MID(I5,2,1)+1&RIGHT(H4,2) -> Q326 | K5: ="Q"&MID(J5,2,1)+1&RIGHT(H4,2) -> Q426 | L5: ="Q1"&RIGHT(L4,2) -> Q127 | M5: ="Q"&MID(L5,2,1)+1&RIGHT(L4,2) -> Q227 | N5: ="Q"&MID(M5,2,1)+1&RIGHT(L4,2) -> Q327 | O5: ="Q"&MID(N5,2,1)+1&RIGHT(L4,2) -> Q427 | P5: ="Q1"&RIGHT(P4,2) -> Q128 | Q5: ="Q"&MID(P5,2,1)+1&RIGHT(P4,2) -> Q228 | R5: ="Q"&MID(Q5,2,1)+1&RIGHT(P4,2) -> Q328 | S5: ="Q"&MID(R5,2,1)+1&RIGHT(P4,2) -> Q428 | T5: ="Q1"&RIGHT(T4,2) -> Q129 | U5: ="Q"&MID(T5,2,1)+1&RIGHT(T4,2) -> Q229 | V5: ="Q"&MID(U5,2,1)+1&RIGHT(T4,2) -> Q329 | W5: ="Q"&MID(V5,2,1)+1&RIGHT(T4,2) -> Q429 | X5: ="Q1"&RIGHT(X4,2) -> Q130 | Y5: ="Q"&MID(X5,2,1)+1&RIGHT(X4,2) -> Q230 | Z5: ="Q"&MID(Y5,2,1)+1&RIGHT(X4,2) -> Q330 | AA5: ="Q"&MID(Z5,2,1)+1&RIGHT(X4,2) -> Q430 | AB5: ="Q1"&RIGHT(AB4,2) -> Q131 | AC5: ="Q"&MID(AB5,2,1)+1&RIGHT(AB4,2) -> Q231 | AD5: ="Q"&MID(AC5,2,1)+1&RIGHT(AB4,2) -> Q331 | AE5: ="Q"&MID(AD5,2,1)+1&RIGHT(AB4,2) -> Q431 | AF5: ="Q1"&RIGHT(AF4,2) -> Q132 | AG5: ="Q"&MID(AF5,2,1)+1&RIGHT(AF4,2) -> Q232 | AH5: ="Q"&MID(AG5,2,1)+1&RIGHT(AF4,2) -> Q332 | AI5: ="Q"&MID(AH5,2,1)+1&RIGHT(AF4,2) -> Q432 | AJ5: Sum HC | AK5: Peak HC | AL5: Rate | AM5: Cost | AN5: HC Profile (mini) | AO5: Check
A6: {=IFERROR(IF(AM6>0,IF(_xlfn.XLOOKUP(F6,INDIRECT(B6),INDIRECT(B6),"NO")="NO","",_xlfn.XLOOKUP($C6,LUT!$B$3:$B$200,LUT!$D$3:$D$200,"")&""),""),"")} -> ATG | B6: Chris | C6: SPG_ADV Technology | D6: Program Management | E6: Canada | F6: alloc_PPL_ATG | G6: Incremental - XCHG | L6: 1 | M6: 1 | N6: 1 | O6: 1 | P6: 1 | Q6: 1 | R6: 1 | S6: 1 | T6: 1 | U6: 1 | V6: 1 | W6: 1 | AJ6: =SUM(H6:AI6) -> 12 | AK6: =MAX(H6:AI6) -> 1 | AL6: =_xlfn.XLOOKUP(E6,Location,labour,0) -> 30138.25 | AM6: =AL6*AJ6 -> 361658.99 | AO6: =IF($AM6>0,IF(AND($G6<>"",$F6<>"",$A6<>"",$B6<>"",$C6<>""),"","Check"),"")
A7: {=IFERROR(IF(AM7>0,IF(_xlfn.XLOOKUP(F7,INDIRECT(B7),INDIRECT(B7),"NO")="NO","",_xlfn.XLOOKUP($C7,LUT!$B$3:$B$200,LUT!$D$3:$D$200,"")&""),""),"")} -> ATG | B7: Chris | C7: SPG_ADV Technology | D7: Architecture/Technical Lead | E7: Canada | F7: alloc_PPL_ATG | G7: Incremental - XCHG | L7: 1 | M7: 1 | N7: 1 | O7: 1 | P7: 1 | Q7: 1 | R7: 1 | S7: 1 | T7: 1 | U7: 1 | V7: 1 | W7: 1 | AJ7: =SUM(H7:AI7) -> 12 | AK7: =MAX(H7:AI7) -> 1 | AL7: =_xlfn.XLOOKUP(E7,Location,labour,0) -> 30138.25 | AM7: =AL7*AJ7 -> 361658.99 | AO7: =IF($AM7>0,IF(AND($G7<>"",$F7<>"",$A7<>"",$B7<>"",$C7<>""),"","Check"),"")
A8: {=IFERROR(IF(AM8>0,IF(_xlfn.XLOOKUP(F8,INDIRECT(B8),INDIRECT(B8),"NO")="NO","",_xlfn.XLOOKUP($C8,LUT!$B$3:$B$200,LUT!$D$3:$D$200,"")&""),""),"")} -> ATG | B8: Chris | C8: SPG_ADV Technology | D8: GNPU - Model enablement/perf optimization | E8: Canada | F8: alloc_PPL_ATG | G8: Incremental - XCHG | M8: 2 | N8: 4 | O8: 4 | P8: 4 | Q8: 4 | R8: 4 | S8: 4 | T8: 4 | U8: 4 | V8: 4 | W8: 2 | AJ8: =SUM(H8:AI8) -> 40 | AK8: =MAX(H8:AI8) -> 4 | AL8: =_xlfn.XLOOKUP(E8,Location,labour,0) -> 30138.25 | AM8: =AL8*AJ8 -> 1205530 | AO8: =IF($AM8>0,IF(AND($G8<>"",$F8<>"",$A8<>"",$B8<>"",$C8<>""),"","Check"),"")
A9: {=IFERROR(IF(AM9>0,IF(_xlfn.XLOOKUP(F9,INDIRECT(B9),INDIRECT(B9),"NO")="NO","",_xlfn.XLOOKUP($C9,LUT!$B$3:$B$200,LUT!$D$3:$D$200,"")&""),""),"")} -> ATG | B9: Chris | C9: SPG_ADV Technology | D9: Android VAS3.0 - Video | E9: Canada | F9: alloc_PPL_ATG | G9: Incremental - XCHG | L9: 1 | M9: 1 | N9: 2 | O9: 2 | P9: 2 | Q9: 4 | R9: 4 | S9: 4 | T9: 4 | U9: 3 | V9: 2 | W9: 2 | AJ9: =SUM(H9:AI9) -> 31 | AK9: =MAX(H9:AI9) -> 4 | AL9: =_xlfn.XLOOKUP(E9,Location,labour,0) -> 30138.25 | AM9: =AL9*AJ9 -> 934285.73
A10: {=IFERROR(IF(AM10>0,IF(_xlfn.XLOOKUP(F10,INDIRECT(B10),INDIRECT(B10),"NO")="NO","",_xlfn.XLOOKUP($C10,LUT!$B$3:$B$200,LUT!$D$3:$D$200,"")&""),""),"")} -> ATG | B10: Chris | C10: SPG_ADV Technology | D10: Android VAS3.0 - Graphics/Display | E10: Canada | F10: alloc_PPL_ATG | G10: Incremental - XCHG | L10: 1 | M10: 1 | N10: 2 | O10: 2 | P10: 2 | Q10: 3 | R10: 3 | S10: 3 | T10: 3 | U10: 3 | V10: 2 | W10: 2 | AJ10: =SUM(H10:AI10) -> 27 | AK10: =MAX(H10:AI10) -> 3 | AL10: =_xlfn.XLOOKUP(E10,Location,labour,0) -> 30138.25 | AM10: =AL10*AJ10 -> 813732.74
A11: {=IFERROR(IF(AM11>0,IF(_xlfn.XLOOKUP(F11,INDIRECT(B11),INDIRECT(B11),"NO")="NO","",_xlfn.XLOOKUP($C11,LUT!$B$3:$B$200,LUT!$D$3:$D$200,"")&""),""),"")} -> ATG | B11: Chris | C11: SPG_ADV Technology | D11: Android VAS3.0 - Security | E11: Canada | F11: alloc_PPL_ATG | G11: Incremental - XCHG | M11: 1 | N11: 1 | O11: 2 | P11: 2 | Q11: 2 | R11: 2 | S11: 2 | T11: 2 | U11: 2 | V11: 2 | W11: 1 | AJ11: =SUM(H11:AI11) -> 19 | AK11: =MAX(H11:AI11) -> 2 | AL11: =_xlfn.XLOOKUP(E11,Location,labour,0) -> 30138.25 | AM11: =AL11*AJ11 -> 572626.74
A12: {=IFERROR(IF(AM12>0,IF(_xlfn.XLOOKUP(F12,INDIRECT(B12),INDIRECT(B12),"NO")="NO","",_xlfn.XLOOKUP($C12,LUT!$B$3:$B$200,LUT!$D$3:$D$200,"")&""),""),"")} -> ATG | B12: Chris | C12: SPG_ADV Technology | D12: Android VAS3.0 - Android Framework | E12: Canada | F12: alloc_PPL_ATG | G12: Incremental - XCHG | M12: 1 | N12: 1 | O12: 2 | P12: 2 | Q12: 2 | R12: 2 | S12: 2 | T12: 2 | U12: 2 | V12: 2 | W12: 1 | AJ12: =SUM(H12:AI12) -> 19 | AK12: =MAX(H12:AI12) -> 2 | AL12: =_xlfn.XLOOKUP(E12,Location,labour,0) -> 30138.25 | AM12: =AL12*AJ12 -> 572626.74
A13: {=IFERROR(IF(AM13>0,IF(_xlfn.XLOOKUP(F13,INDIRECT(B13),INDIRECT(B13),"NO")="NO","",_xlfn.XLOOKUP($C13,LUT!$B$3:$B$200,LUT!$D$3:$D$200,"")&""),""),"")} -> ATG | B13: Chris | C13: SPG_ADV Technology | D13: Heterogeneous Compute Acceleration (CPU/GPU/GNPU) | E13: Canada | F13: alloc_PPL_ATG | G13: Incremental - XCHG | L13: 1 | M13: 2 | N13: 4 | O13: 6 | P13: 4 | Q13: 8 | R13: 8 | S13: 8 | T13: 8 | U13: 6 | V13: 6 | W13: 4 | AJ13: =SUM(H13:AI13) -> 65 | AK13: =MAX(H13:AI13) -> 8 | AL13: =_xlfn.XLOOKUP(E13,Location,labour,0) -> 30138.25 | AM13: =AL13*AJ13 -> 1958986.2
A14: {=IFERROR(IF(AM14>0,IF(_xlfn.XLOOKUP(F14,INDIRECT(B14),INDIRECT(B14),"NO")="NO","",_xlfn.XLOOKUP($C14,LUT!$B$3:$B$200,LUT!$D$3:$D$200,"")&""),""),"")} -> ATG | B14: Chris | C14: SPG_ADV Technology | D14: ROCm on Android/Virtualization | E14: Canada | F14: alloc_PPL_ATG | G14: Incremental - XCHG | L14: 1 | M14: 2 | N14: 2 | O14: 2 | P14: 4 | Q14: 4 | R14: 4 | S14: 4 | T14: 4 | U14: 4 | V14: 2 | W14: 2 | AJ14: =SUM(H14:AI14) -> 35 | AK14: =MAX(H14:AI14) -> 4 | AL14: =_xlfn.XLOOKUP(E14,Location,labour,0) -> 30138.25 | AM14: =AL14*AJ14 -> 1054838.7
A15: {=IFERROR(IF(AM15>0,IF(_xlfn.XLOOKUP(F15,INDIRECT(B15),INDIRECT(B15),"NO")="NO","",_xlfn.XLOOKUP($C15,LUT!$B$3:$B$200,LUT!$D$3:$D$200,"")&""),""),"")} -> ATG | B15: Chris | C15: SPG_ADV Technology | D15: FuSA consulting/support | E15: Canada | F15: alloc_PPL_ATG | G15: Incremental - XCHG | L15: 1 | M15: 1 | N15: 1 | O15: 1 | P15: 1 | Q15: 1 | R15: 1 | S15: 1 | T15: 1 | U15: 1 | V15: 1 | W15: 1 | AJ15: =SUM(H15:AI15) -> 12 | AK15: =MAX(H15:AI15) -> 1 | AL15: =_xlfn.XLOOKUP(E15,Location,labour,0) -> 30138.25 | AM15: =AL15*AJ15 -> 361658.99 | AO15: =IF($AM15>0,IF(AND($G15<>"",$F15<>"",$A15<>"",$B15<>"",$C15<>""),"","Check"),"")
A16: {=IFERROR(IF(AM16>0,IF(_xlfn.XLOOKUP(F16,INDIRECT(B16),INDIRECT(B16),"NO")="NO","",_xlfn.XLOOKUP($C16,LUT!$B$3:$B$200,LUT!$D$3:$D$200,"")&""),""),"")} -> ATG | B16: Chris | C16: SPG_ADV Technology | D16: Validation QA + DevOps | E16: Canada | F16: alloc_PPL_ATG | G16: Incremental - XCHG | K16: 1 | L16: 2 | M16: 3 | N16: 3 | O16: 3 | P16: 3 | Q16: 5 | R16: 5 | S16: 5 | T16: 5 | U16: 3 | V16: 3 | W16: 3 | AJ16: =SUM(H16:AI16) -> 44 | AK16: =MAX(H16:AI16) -> 5 | AL16: =_xlfn.XLOOKUP(E16,Location,labour,0) -> 30138.25 | AM16: =AL16*AJ16 -> 1326083 | AO16: =IF($AM16>0,IF(AND($G16<>"",$F16<>"",$A16<>"",$B16<>"",$C16<>""),"","Check"),"")
A17: {=IFERROR(IF(AM17>0,IF(_xlfn.XLOOKUP(F17,INDIRECT(B17),INDIRECT(B17),"NO")="NO","",_xlfn.XLOOKUP($C17,LUT!$B$3:$B$200,LUT!$D$3:$D$200,"")&""),""),"")} -> PlatLinux | B17: Chris | C17: SPG_Platform_Linux | D17: Linux - KFD KGD ROCr/Thunk on Baremetal/PM/SMI/MM/BPI | E17: Canada | F17: alloc_MLS_Linux_4 | G17: Incremental - XCHG | K17: 1 | L17: 2 | M17: 2 | N17: 2 | O17: 2 | P17: 2 | Q17: 2 | R17: 2 | S17: 2 | T17: 2 | U17: 2 | V17: 2 | W17: 2 | X17: 1 | AJ17: =SUM(H17:AI17) -> 26 | AK17: =MAX(H17:AI17) -> 2 | AL17: =_xlfn.XLOOKUP(E17,Location,labour,0) -> 30138.25 | AM17: =AL17*AJ17 -> 783594.49 | AO17: =IF($AM17>0,IF(AND($G17<>"",$F17<>"",$A17<>"",$B17<>"",$C17<>""),"","Check"),"")
A18: {=IFERROR(IF(AM18>0,IF(_xlfn.XLOOKUP(F18,INDIRECT(B18),INDIRECT(B18),"NO")="NO","",_xlfn.XLOOKUP($C18,LUT!$B$3:$B$200,LUT!$D$3:$D$200,"")&""),""),"")} -> PlatLinux | B18: Chris | C18: SPG_Platform_Linux | D18: Linux Dev /Virtualization/ROCm DOMU/IQE | E18: China Shanghai | F18: alloc_MLS_Linux_3 | G18: Incremental - XCHG | J18: 0.5 | K18: 0.5 | L18: 0.5 | M18: 0.5 | N18: 0.5 | O18: 0.5 | P18: 0.5 | Q18: 9 | R18: 10 | S18: 13 | T18: 13 | U18: 13 | V18: 11 | W18: 9 | X18: 6 | AJ18: =SUM(H18:AI18) -> 87.5 | AK18: =MAX(H18:AI18) -> 13 | AL18: =_xlfn.XLOOKUP(E18,Location,labour,0) -> 27275.209 | AM18: =AL18*AJ18 -> 2386580.8 | AO18: =IF($AM18>0,IF(AND($G18<>"",$F18<>"",$A18<>"",$B18<>"",$C18<>""),"","Check"),"")
A19: {=IFERROR(IF(AM19>0,IF(_xlfn.XLOOKUP(F19,INDIRECT(B19),INDIRECT(B19),"NO")="NO","",_xlfn.XLOOKUP($C19,LUT!$B$3:$B$200,LUT!$D$3:$D$200,"")&""),""),"")} -> PlatLinux | B19: Chris | C19: SPG_Platform_Linux | D19: VirtIO GPU emulation - Xen/QEMU/Virglrenderer DOM0 (Graphics - Windows) | E19: China Shanghai | F19: alloc_MLS_Linux_3 | G19: Incremental - XCHG | Q19: 1 | R19: 1 | S19: 2 | T19: 2 | U19: 2 | V19: 2 | W19: 1 | X19: 1 | AJ19: =SUM(H19:AI19) -> 12 | AK19: =MAX(H19:AI19) -> 2 | AL19: =_xlfn.XLOOKUP(E19,Location,labour,0) -> 27275.209 | AM19: =AL19*AJ19 -> 327302.51
A20: {=IFERROR(IF(AM20>0,IF(_xlfn.XLOOKUP(F20,INDIRECT(B20),INDIRECT(B20),"NO")="NO","",_xlfn.XLOOKUP($C20,LUT!$B$3:$B$200,LUT!$D$3:$D$200,"")&""),""),"")} -> PlatLinux | B20: Chris | C20: SPG_Platform_Linux | D20: Display Virtualization (Windows) | E20: China Shanghai | F20: alloc_MLS_Linux_3 | G20: Incremental - XCHG | Q20: 0.5 | R20: 1 | S20: 1 | T20: 1 | U20: 1 | V20: 1 | W20: 1 | X20: 0.5 | AJ20: =SUM(H20:AI20) -> 7 | AK20: =MAX(H20:AI20) -> 1 | AL20: =_xlfn.XLOOKUP(E20,Location,labour,0) -> 27275.209 | AM20: =AL20*AJ20 -> 190926.46
A21: {=IFERROR(IF(AM21>0,IF(_xlfn.XLOOKUP(F21,INDIRECT(B21),INDIRECT(B21),"NO")="NO","",_xlfn.XLOOKUP($C21,LUT!$B$3:$B$200,LUT!$D$3:$D$200,"")&""),""),"")} -> PlatLinux | B21: Chris | C21: SPG_Platform_Linux | D21: Graphics Virtualization - Guest Windows KMD | E21: China Shanghai | F21: alloc_MLS_Linux_3 | G21: Incremental - XCHG | Q21: 1 | R21: 1 | S21: 2 | T21: 2 | U21: 2 | V21: 2 | W21: 1 | X21: 1 | AJ21: =SUM(H21:AI21) -> 12 | AK21: =MAX(H21:AI21) -> 2 | AL21: =_xlfn.XLOOKUP(E21,Location,labour,0) -> 27275.209 | AM21: =AL21*AJ21 -> 327302.51
A22: {=IFERROR(IF(AM22>0,IF(_xlfn.XLOOKUP(F22,INDIRECT(B22),INDIRECT(B22),"NO")="NO","",_xlfn.XLOOKUP($C22,LUT!$B$3:$B$200,LUT!$D$3:$D$200,"")&""),""),"")} -> PlatLinux | B22: Chris | C22: SPG_Platform_Linux | D22: Graphics Virtualization - Guest Windows UMD (Virgl) | E22: China Shanghai | F22: alloc_MLS_Linux_3 | G22: Incremental - XCHG | Q22: 0.5 | R22: 1 | S22: 1 | T22: 1 | U22: 1 | V22: 1 | W22: 1 | X22: 0.5 | AJ22: =SUM(H22:AI22) -> 7 | AK22: =MAX(H22:AI22) -> 1 | AL22: =_xlfn.XLOOKUP(E22,Location,labour,0) -> 27275.209 | AM22: =AL22*AJ22 -> 190926.46
A23: {=IFERROR(IF(AM23>0,IF(_xlfn.XLOOKUP(F23,INDIRECT(B23),INDIRECT(B23),"NO")="NO","",_xlfn.XLOOKUP($C23,LUT!$B$3:$B$200,LUT!$D$3:$D$200,"")&""),""),"")} -> PlatLinux | B23: Chris | C23: SPG_Platform_Linux | D23: Graphics Virtualization - Guest Android (Issue Debugging Support) | E23: China Shanghai | F23: alloc_MLS_Linux_3 | G23: Incremental - XCHG | Q23: 1 | R23: 1 | S23: 2 | T23: 3 | U23: 3 | V23: 3 | W23: 3 | X23: 3 | AJ23: =SUM(H23:AI23) -> 19 | AK23: =MAX(H23:AI23) -> 3 | AL23: =_xlfn.XLOOKUP(E23,Location,labour,0) -> 27275.209 | AM23: =AL23*AJ23 -> 518228.97
A24: Disp&MM | B24: Syed | C24: SPG_Display NPI | D24: Charlie Wang | E24: Canada | F24: alloc_Display Solution_CharlieW | G24: Incremental - XCHG | P24: 2 | Q24: 2 | R24: 2 | S24: 3 | T24: 2 | U24: 2 | V24: 2 | W24: 2 | AJ24: =SUM(H24:AI24) -> 17 | AK24: =MAX(H24:AI24) -> 3 | AL24: =_xlfn.XLOOKUP(E24,Location,labour,0) -> 30138.25 | AM24: =AL24*AJ24 -> 512350.24 | AO24: =IF($AM24>0,IF(AND($G24<>"",$F24<>"",$A24<>"",$B24<>"",$C24<>""),"","Check"),"")
A25: {=IFERROR(IF(AM25>0,IF(_xlfn.XLOOKUP(F25,INDIRECT(B25),INDIRECT(B25),"NO")="NO","",_xlfn.XLOOKUP($C25,LUT!$B$3:$B$200,LUT!$D$3:$D$200,"")&""),""),"")} | AD25: 0 | AE25: 0 | AJ25: =SUM(H25:AI25) -> 0 | AK25: =MAX(H25:AI25) -> 0 | AL25: =_xlfn.XLOOKUP(E25,Location,labour,0) -> 0 | AM25: =AL25*AJ25 -> 0 | AO25: =IF($AM25>0,IF(AND($G25<>"",$F25<>"",$A25<>"",$B25<>"",$C25<>""),"","Check"),"")
A26: {=IFERROR(IF(AM26>0,IF(_xlfn.XLOOKUP(F26,INDIRECT(B26),INDIRECT(B26),"NO")="NO","",_xlfn.XLOOKUP($C26,LUT!$B$3:$B$200,LUT!$D$3:$D$200,"")&""),""),"")} | AJ26: =SUM(H26:AI26) -> 0 | AK26: =MAX(H26:AI26) -> 0 | AL26: =_xlfn.XLOOKUP(E26,Location,labour,0) -> 0 | AM26: =AL26*AJ26 -> 0
A27: {=IFERROR(IF(AM27>0,IF(_xlfn.XLOOKUP(F27,INDIRECT(B27),INDIRECT(B27),"NO")="NO","",_xlfn.XLOOKUP($C27,LUT!$B$3:$B$200,LUT!$D$3:$D$200,"")&""),""),"")} | AJ27: =SUM(H27:AI27) -> 0 | AK27: =MAX(H27:AI27) -> 0 | AL27: =_xlfn.XLOOKUP(E27,Location,labour,0) -> 0 | AM27: =AL27*AJ27 -> 0
A28: {=IFERROR(IF(AM28>0,IF(_xlfn.XLOOKUP(F28,INDIRECT(B28),INDIRECT(B28),"NO")="NO","",_xlfn.XLOOKUP($C28,LUT!$B$3:$B$200,LUT!$D$3:$D$200,"")&""),""),"")} | AJ28: =SUM(H28:AI28) -> 0 | AK28: =MAX(H28:AI28) -> 0 | AL28: =_xlfn.XLOOKUP(E28,Location,labour,0) -> 0 | AM28: =AL28*AJ28 -> 0
A29: {=IFERROR(IF(AM29>0,IF(_xlfn.XLOOKUP(F29,INDIRECT(B29),INDIRECT(B29),"NO")="NO","",_xlfn.XLOOKUP($C29,LUT!$B$3:$B$200,LUT!$D$3:$D$200,"")&""),""),"")} | AJ29: =SUM(H29:AI29) -> 0 | AK29: =MAX(H29:AI29) -> 0 | AL29: =_xlfn.XLOOKUP(E29,Location,labour,0) -> 0 | AM29: =AL29*AJ29 -> 0 | AO29: =IF($AM29>0,IF(AND($G29<>"",$F29<>"",$A29<>"",$B29<>"",$C29<>""),"","Check"),"")
A30: {=IFERROR(IF(AM30>0,IF(_xlfn.XLOOKUP(F30,INDIRECT(B30),INDIRECT(B30),"NO")="NO","",_xlfn.XLOOKUP($C30,LUT!$B$3:$B$200,LUT!$D$3:$D$200,"")&""),""),"")} | AJ30: =SUM(H30:AI30) -> 0 | AK30: =MAX(H30:AI30) -> 0 | AL30: =_xlfn.XLOOKUP(E30,Location,labour,0) -> 0 | AM30: =AL30*AJ30 -> 0
A31: {=IFERROR(IF(AM31>0,IF(_xlfn.XLOOKUP(F31,INDIRECT(B31),INDIRECT(B31),"NO")="NO","",_xlfn.XLOOKUP($C31,LUT!$B$3:$B$200,LUT!$D$3:$D$200,"")&""),""),"")} | AJ31: =SUM(H31:AI31) -> 0 | AK31: =MAX(H31:AI31) -> 0 | AL31: =_xlfn.XLOOKUP(E31,Location,labour,0) -> 0 | AM31: =AL31*AJ31 -> 0 | AO31: =IF($AM31>0,IF(AND($G31<>"",$F31<>"",$A31<>"",$B31<>"",$C31<>""),"","Check"),"")
A32: {=IFERROR(IF(AM32>0,IF(_xlfn.XLOOKUP(F32,INDIRECT(B32),INDIRECT(B32),"NO")="NO","",_xlfn.XLOOKUP($C32,LUT!$B$3:$B$200,LUT!$D$3:$D$200,"")&""),""),"")} | AJ32: =SUM(H32:AI32) -> 0 | AK32: =MAX(H32:AI32) -> 0 | AL32: =_xlfn.XLOOKUP(E32,Location,labour,0) -> 0 | AM32: =AL32*AJ32 -> 0 | AO32: =IF($AM32>0,IF(AND($G32<>"",$F32<>"",$A32<>"",$B32<>"",$C32<>""),"","Check"),"")
A33: {=IFERROR(IF(AM33>0,IF(_xlfn.XLOOKUP(F33,INDIRECT(B33),INDIRECT(B33),"NO")="NO","",_xlfn.XLOOKUP($C33,LUT!$B$3:$B$200,LUT!$D$3:$D$200,"")&""),""),"")} | AJ33: =SUM(H33:AI33) -> 0 | AK33: =MAX(H33:AI33) -> 0 | AL33: =_xlfn.XLOOKUP(E33,Location,labour,0) -> 0 | AM33: =AL33*AJ33 -> 0 | AO33: =IF($AM33>0,IF(AND($G33<>"",$F33<>"",$A33<>"",$B33<>"",$C33<>""),"","Check"),"")
A34: {=IFERROR(IF(AM34>0,IF(_xlfn.XLOOKUP(F34,INDIRECT(B34),INDIRECT(B34),"NO")="NO","",_xlfn.XLOOKUP($C34,LUT!$B$3:$B$200,LUT!$D$3:$D$200,"")&""),""),"")} | AJ34: =SUM(H34:AI34) -> 0 | AK34: =MAX(H34:AI34) -> 0 | AL34: =_xlfn.XLOOKUP(E34,Location,labour,0) -> 0 | AM34: =AL34*AJ34 -> 0 | AO34: =IF($AM34>0,IF(AND($G34<>"",$F34<>"",$A34<>"",$B34<>"",$C34<>""),"","Check"),"")
A35: {=IFERROR(IF(AM35>0,IF(_xlfn.XLOOKUP(F35,INDIRECT(B35),INDIRECT(B35),"NO")="NO","",_xlfn.XLOOKUP($C35,LUT!$B$3:$B$200,LUT!$D$3:$D$200,"")&""),""),"")} | AJ35: =SUM(H35:AI35) -> 0 | AK35: =MAX(H35:AI35) -> 0 | AL35: =_xlfn.XLOOKUP(E35,Location,labour,0) -> 0 | AM35: =AL35*AJ35 -> 0 | AO35: =IF($AM35>0,IF(AND($G35<>"",$F35<>"",$A35<>"",$B35<>"",$C35<>""),"","Check"),"")
A36: {=IFERROR(IF(AM36>0,IF(_xlfn.XLOOKUP(F36,INDIRECT(B36),INDIRECT(B36),"NO")="NO","",_xlfn.XLOOKUP($C36,LUT!$B$3:$B$200,LUT!$D$3:$D$200,"")&""),""),"")} | AJ36: =SUM(H36:AI36) -> 0 | AK36: =MAX(H36:AI36) -> 0 | AL36: =_xlfn.XLOOKUP(E36,Location,labour,0) -> 0 | AM36: =AL36*AJ36 -> 0 | AO36: =IF($AM36>0,IF(AND($G36<>"",$F36<>"",$A36<>"",$B36<>"",$C36<>""),"","Check"),"")
A37: {=IFERROR(IF(AM37>0,IF(_xlfn.XLOOKUP(F37,INDIRECT(B37),INDIRECT(B37),"NO")="NO","",_xlfn.XLOOKUP($C37,LUT!$B$3:$B$200,LUT!$D$3:$D$200,"")&""),""),"")} | AJ37: =SUM(H37:AI37) -> 0 | AK37: =MAX(H37:AI37) -> 0 | AL37: =_xlfn.XLOOKUP(E37,Location,labour,0) -> 0 | AM37: =AL37*AJ37 -> 0 | AO37: =IF($AM37>0,IF(AND($G37<>"",$F37<>"",$A37<>"",$B37<>"",$C37<>""),"","Check"),"")
A38: {=IFERROR(IF(AM38>0,IF(_xlfn.XLOOKUP(F38,INDIRECT(B38),INDIRECT(B38),"NO")="NO","",_xlfn.XLOOKUP($C38,LUT!$B$3:$B$200,LUT!$D$3:$D$200,"")&""),""),"")} | AJ38: =SUM(H38:AI38) -> 0 | AK38: =MAX(H38:AI38) -> 0 | AL38: =_xlfn.XLOOKUP(E38,Location,labour,0) -> 0 | AM38: =AL38*AJ38 -> 0 | AO38: =IF($AM38>0,IF(AND($G38<>"",$F38<>"",$A38<>"",$B38<>"",$C38<>""),"","Check"),"")
A39: {=IFERROR(IF(AM39>0,IF(_xlfn.XLOOKUP(F39,INDIRECT(B39),INDIRECT(B39),"NO")="NO","",_xlfn.XLOOKUP($C39,LUT!$B$3:$B$200,LUT!$D$3:$D$200,"")&""),""),"")} | AJ39: =SUM(H39:AI39) -> 0 | AK39: =MAX(H39:AI39) -> 0 | AL39: =_xlfn.XLOOKUP(E39,Location,labour,0) -> 0 | AM39: =AL39*AJ39 -> 0 | AO39: =IF($AM39>0,IF(AND($G39<>"",$F39<>"",$A39<>"",$B39<>"",$C39<>""),"","Check"),"")
A40: {=IFERROR(IF(AM40>0,IF(_xlfn.XLOOKUP(F40,INDIRECT(B40),INDIRECT(B40),"NO")="NO","",_xlfn.XLOOKUP($C40,LUT!$B$3:$B$200,LUT!$D$3:$D$200,"")&""),""),"")} | AJ40: =SUM(H40:AI40) -> 0 | AK40: =MAX(H40:AI40) -> 0 | AL40: =_xlfn.XLOOKUP(E40,Location,labour,0) -> 0 | AM40: =AL40*AJ40 -> 0 | AO40: =IF($AM40>0,IF(AND($G40<>"",$F40<>"",$A40<>"",$B40<>"",$C40<>""),"","Check"),"")
...

Sheet Capitola C40 v1.0 r1
A1: =_xlfn.XLOOKUP(AN2,Status,statusnote,"",0,1) -> Sizing is CLOSED. This sheet is LOCKED and PROTECTED from editing. NO CHANGES are permitted while locked. Please contact Sam Huynh if you need to make any modifications. | AN1: Status
A2: {=MID(CELL("filename",A1),FIND("]",CELL("filename",A1))+1,256)} -> Capitola C40 v1.0 r1 | D2: Notes: BU - AECG REFERENCE ONLY - DO NOT EDIT OR MAKE CHANGES TO THIS SIZING | AN2: Complete
A3: Last Updated | C3: 46168 | D3: Schedule Milestones>> | L3: LSA | M3: LSB | N3: LSC | O3: LSD | P3: BTO | Q3: UU | V3: IP
D4: Resource Allocation | H4: 2026 | L4: =H4+1 -> 2027 | P4: =L4+1 -> 2028 | T4: =P4+1 -> 2029 | X4: =T4+1 -> 2030 | AB4: =X4+1 -> 2031 | AF4: =AB4+1 -> 2032 | AJ4: =SUBTOTAL(9,AJ6:AJ64) -> 634.6 | AK4: =SUBTOTAL(9,AK6:AK64) -> 76 | AL4: =AVERAGE(AL6:AL64) -> 16666.539 | AM4: =SUBTOTAL(9,AM6:AM64) -> 19038735
A5: Category | B5: Leader | C5: Top Level Team | D5: Function / Contact | E5: Location | F5: Allocation File | G5: HC Type | H5: ="Q1"&RIGHT(H4,2) -> Q126 | I5: ="Q"&MID(H5,2,1)+1&RIGHT(H4,2) -> Q226 | J5: ="Q"&MID(I5,2,1)+1&RIGHT(H4,2) -> Q326 | K5: ="Q"&MID(J5,2,1)+1&RIGHT(H4,2) -> Q426 | L5: ="Q1"&RIGHT(L4,2) -> Q127 | M5: ="Q"&MID(L5,2,1)+1&RIGHT(L4,2) -> Q227 | N5: ="Q"&MID(M5,2,1)+1&RIGHT(L4,2) -> Q327 | O5: ="Q"&MID(N5,2,1)+1&RIGHT(L4,2) -> Q427 | P5: ="Q1"&RIGHT(P4,2) -> Q128 | Q5: ="Q"&MID(P5,2,1)+1&RIGHT(P4,2) -> Q228 | R5: ="Q"&MID(Q5,2,1)+1&RIGHT(P4,2) -> Q328 | S5: ="Q"&MID(R5,2,1)+1&RIGHT(P4,2) -> Q428 | T5: ="Q1"&RIGHT(T4,2) -> Q129 | U5: ="Q"&MID(T5,2,1)+1&RIGHT(T4,2) -> Q229 | V5: ="Q"&MID(U5,2,1)+1&RIGHT(T4,2) -> Q329 | W5: ="Q"&MID(V5,2,1)+1&RIGHT(T4,2) -> Q429 | X5: ="Q1"&RIGHT(X4,2) -> Q130 | Y5: ="Q"&MID(X5,2,1)+1&RIGHT(X4,2) -> Q230 | Z5: ="Q"&MID(Y5,2,1)+1&RIGHT(X4,2) -> Q330 | AA5: ="Q"&MID(Z5,2,1)+1&RIGHT(X4,2) -> Q430 | AB5: ="Q1"&RIGHT(AB4,2) -> Q131 | AC5: ="Q"&MID(AB5,2,1)+1&RIGHT(AB4,2) -> Q231 | AD5: ="Q"&MID(AC5,2,1)+1&RIGHT(AB4,2) -> Q331 | AE5: ="Q"&MID(AD5,2,1)+1&RIGHT(AB4,2) -> Q431 | AF5: ="Q1"&RIGHT(AF4,2) -> Q132 | AG5: ="Q"&MID(AF5,2,1)+1&RIGHT(AF4,2) -> Q232 | AH5: ="Q"&MID(AG5,2,1)+1&RIGHT(AF4,2) -> Q332 | AI5: ="Q"&MID(AH5,2,1)+1&RIGHT(AF4,2) -> Q432 | AJ5: Sum HC | AK5: Peak HC | AL5: Rate | AM5: Cost | AN5: HC Profile (mini) | AO5: Check
A6: {=IFERROR(IF(AM6>0,IF(_xlfn.XLOOKUP(F6,INDIRECT(B6),INDIRECT(B6),"NO")="NO","",_xlfn.XLOOKUP($C6,LUT!$B$3:$B$200,LUT!$D$3:$D$200,"")&""),""),"")} -> ATG | B6: Chris | C6: SPG_ADV Technology | D6: Program Management | E6: Global | F6: alloc_PPL_ATG | G6: Incremental - XCHG | L6: 1 | M6: 1 | N6: 1 | O6: 1 | P6: 1 | Q6: 1 | R6: 1 | S6: 1 | T6: 1 | U6: 1 | V6: 1 | W6: 1 | AJ6: =SUM(H6:AI6) -> 12 | AK6: =MAX(H6:AI6) -> 1 | AL6: =_xlfn.XLOOKUP(E6,Location,labour,0) -> 31000 | AM6: =AL6*AJ6 -> 372000 | AO6: =IF($AM6>0,IF(AND($G6<>"",$F6<>"",$A6<>"",$B6<>"",$C6<>""),"","Check"),"")
A7: {=IFERROR(IF(AM7>0,IF(_xlfn.XLOOKUP(F7,INDIRECT(B7),INDIRECT(B7),"NO")="NO","",_xlfn.XLOOKUP($C7,LUT!$B$3:$B$200,LUT!$D$3:$D$200,"")&""),""),"")} -> ATG | B7: Chris | C7: SPG_ADV Technology | D7: Architecture/Technical Lead | E7: Global | F7: alloc_PPL_ATG | G7: Incremental - XCHG | L7: 1 | M7: 1 | N7: 1 | O7: 1 | P7: 1 | Q7: 1 | R7: 1 | S7: 1 | T7: 1 | U7: 1 | V7: 1 | W7: 1 | AJ7: =SUM(H7:AI7) -> 12 | AK7: =MAX(H7:AI7) -> 1 | AL7: =_xlfn.XLOOKUP(E7,Location,labour,0) -> 31000 | AM7: =AL7*AJ7 -> 372000 | AO7: =IF($AM7>0,IF(AND($G7<>"",$F7<>"",$A7<>"",$B7<>"",$C7<>""),"","Check"),"")
A8: {=IFERROR(IF(AM8>0,IF(_xlfn.XLOOKUP(F8,INDIRECT(B8),INDIRECT(B8),"NO")="NO","",_xlfn.XLOOKUP($C8,LUT!$B$3:$B$200,LUT!$D$3:$D$200,"")&""),""),"")} -> ATG | B8: Chris | C8: SPG_ADV Technology | D8: GNPU - Model enablement/perf optimization | E8: Global | F8: alloc_PPL_ATG | G8: Incremental - XCHG | M8: 2 | N8: 4 | O8: 4 | P8: 4 | Q8: 4 | R8: 4 | S8: 4 | T8: 4 | U8: 4 | V8: 4 | W8: 2 | AJ8: =SUM(H8:AI8) -> 40 | AK8: =MAX(H8:AI8) -> 4 | AL8: =_xlfn.XLOOKUP(E8,Location,labour,0) -> 31000 | AM8: =AL8*AJ8 -> 1240000 | AO8: =IF($AM8>0,IF(AND($G8<>"",$F8<>"",$A8<>"",$B8<>"",$C8<>""),"","Check"),"")
A9: {=IFERROR(IF(AM9>0,IF(_xlfn.XLOOKUP(F9,INDIRECT(B9),INDIRECT(B9),"NO")="NO","",_xlfn.XLOOKUP($C9,LUT!$B$3:$B$200,LUT!$D$3:$D$200,"")&""),""),"")} -> ATG | B9: Chris | C9: SPG_ADV Technology | D9: Android VAS3.0 - Video | E9: Global | F9: alloc_PPL_ATG | G9: Incremental - XCHG | L9: 1 | M9: 1 | N9: 2 | O9: 2 | P9: 2 | Q9: 4 | R9: 4 | S9: 4 | T9: 4 | U9: 3 | V9: 2 | W9: 2 | AJ9: =SUM(H9:AI9) -> 31 | AK9: =MAX(H9:AI9) -> 4 | AL9: =_xlfn.XLOOKUP(E9,Location,labour,0) -> 31000 | AM9: =AL9*AJ9 -> 961000
A10: {=IFERROR(IF(AM10>0,IF(_xlfn.XLOOKUP(F10,INDIRECT(B10),INDIRECT(B10),"NO")="NO","",_xlfn.XLOOKUP($C10,LUT!$B$3:$B$200,LUT!$D$3:$D$200,"")&""),""),"")} -> ATG | B10: Chris | C10: SPG_ADV Technology | D10: Android VAS3.0 - Graphics/Display | E10: Global | F10: alloc_PPL_ATG | G10: Incremental - XCHG | L10: 1 | M10: 1 | N10: 2 | O10: 2 | P10: 2 | Q10: 3 | R10: 3 | S10: 3 | T10: 3 | U10: 3 | V10: 2 | W10: 2 | AJ10: =SUM(H10:AI10) -> 27 | AK10: =MAX(H10:AI10) -> 3 | AL10: =_xlfn.XLOOKUP(E10,Location,labour,0) -> 31000 | AM10: =AL10*AJ10 -> 837000
A11: {=IFERROR(IF(AM11>0,IF(_xlfn.XLOOKUP(F11,INDIRECT(B11),INDIRECT(B11),"NO")="NO","",_xlfn.XLOOKUP($C11,LUT!$B$3:$B$200,LUT!$D$3:$D$200,"")&""),""),"")} -> ATG | B11: Chris | C11: SPG_ADV Technology | D11: Android VAS3.0 - Security | E11: Global | F11: alloc_PPL_ATG | G11: Incremental - XCHG | M11: 1 | N11: 1 | O11: 2 | P11: 2 | Q11: 2 | R11: 2 | S11: 2 | T11: 2 | U11: 2 | V11: 2 | W11: 1 | AJ11: =SUM(H11:AI11) -> 19 | AK11: =MAX(H11:AI11) -> 2 | AL11: =_xlfn.XLOOKUP(E11,Location,labour,0) -> 31000 | AM11: =AL11*AJ11 -> 589000
A12: {=IFERROR(IF(AM12>0,IF(_xlfn.XLOOKUP(F12,INDIRECT(B12),INDIRECT(B12),"NO")="NO","",_xlfn.XLOOKUP($C12,LUT!$B$3:$B$200,LUT!$D$3:$D$200,"")&""),""),"")} -> ATG | B12: Chris | C12: SPG_ADV Technology | D12: Android VAS3.0 - Android Framework | E12: Global | F12: alloc_PPL_ATG | G12: Incremental - XCHG | M12: 1 | N12: 1 | O12: 2 | P12: 2 | Q12: 2 | R12: 2 | S12: 2 | T12: 2 | U12: 2 | V12: 2 | W12: 1 | AJ12: =SUM(H12:AI12) -> 19 | AK12: =MAX(H12:AI12) -> 2 | AL12: =_xlfn.XLOOKUP(E12,Location,labour,0) -> 31000 | AM12: =AL12*AJ12 -> 589000
