Workbook
Name Chris: _xlfn.ANCHORARRAY(LUT!$O$3)
Name ChrisTeam: _xlfn.ANCHORARRAY(LUT!$W$3)
Name CVP: LUT!$M$3:$M$9
Name HCType: LUT!$G$3:$G$6
Name Hugo: _xlfn.ANCHORARRAY(LUT!$P$3)
Name HugoTeam: _xlfn.ANCHORARRAY(LUT!$X$3)
Name Jeffrey: _xlfn.ANCHORARRAY(LUT!$U$3)
Name JeffreyTeam: _xlfn.ANCHORARRAY(LUT!$AC$3)
Name labour: LUT!$H$3:$H$26
Name Location: LUT!$I$3:$I$26
Name Matthias: _xlfn.ANCHORARRAY(LUT!$Q$3)
Name MatthiasTeam: _xlfn.ANCHORARRAY(LUT!$Y$3)
Name Rodney: LUT!$N$3
Name RodneyTeam: _xlfn.ANCHORARRAY(LUT!$V$3)
Name Scenarios: 'Ramp Scenarios'!$B$3:$B$11
Name Status: LUT!$J$3:$J$12
Name statusnote: LUT!$K$3:$K$12
Name Stephen: _xlfn.ANCHORARRAY(LUT!$R$3)
Name StephenTeam: _xlfn.ANCHORARRAY(LUT!$Z$3)
Name Syed: _xlfn.ANCHORARRAY(LUT!$S$3)
Name SyedTeam: _xlfn.ANCHORARRAY(LUT!$AA$3)
Name Terry: _xlfn.ANCHORARRAY(LUT!$T$3)
Name TerryTeam: _xlfn.ANCHORARRAY(LUT!$AB$3)

Sheet Capitola v1.0
D1: Architecture / Planning | E1: Solution architect on-board (0.5 HC), PM/arch support starting (0.2 HC). Pre-program alignment.
D2: Pre-SI Ramp | E2: Program management, solution arch at steady 0.5. Pre-SI emulation kicks in Q4 FY27.
D3: Silicon Bringup (NPI) | E3: Major ramp. NPI support, Pre-SI emulation, all development teams start. HC jumps from 5.5 → 18 → 25 in Q128→Q228→Q328.
D4: Peak Development | E4: All virtualization, ROCm, graphics, IQE at full strength. Peak HC = 31.6 in Q1 FY29
D5: Integration / Validation | E5: HC winds down from 30 → 22 → 15. Feature complete, validation cycles.
D6: Sustaining / Long Tail | E6: 13.3 HC in Q4 FY29, tapering to ~0 by end of FY30. Maintenance and customer use-case support.
A9: =_xlfn.XLOOKUP(AM10,Status,statusnote,"",0,1) -> Sizing is OPEN. Please UPDATE your estimates for your teams in this sheet. Also UPDATE the scope, assumptions and risks in the Assumptions tab. | AM9: Status
A10: Capitola v1.0 | D10: Notes: BU - BU - AECG • | AM10: In Progress
A11: Last Updated | C11: 46134 | D11: Schedule Milestones>>
D12: Resource Allocation | I12: 2026 | M12: =I12+1 -> 2027 | Q12: =M12+1 -> 2028 | U12: =Q12+1 -> 2029 | Y12: =U12+1 -> 2030 | AC12: =Y12+1 -> 2031 | AG12: =AC12+1 -> 2032 | AK12: =SUBTOTAL(9,AK14:AK66) -> 185.3 | AL12: =SUBTOTAL(9,AL14:AL66) -> 32.7
A13: Category | B13: Leader | C13: Top Level Team | D13: Function / Contact | E13: Scope of work | F13: Location | G13: Allocation File | H13: HC Type | I13: ="Q1"&RIGHT(I12,2) -> Q126 | J13: ="Q"&MID(I13,2,1)+1&RIGHT(I12,2) -> Q226 | K13: ="Q"&MID(J13,2,1)+1&RIGHT(I12,2) -> Q326 | L13: ="Q"&MID(K13,2,1)+1&RIGHT(I12,2) -> Q426 | M13: ="Q1"&RIGHT(M12,2) -> Q127 | N13: ="Q"&MID(M13,2,1)+1&RIGHT(M12,2) -> Q227 | O13: ="Q"&MID(N13,2,1)+1&RIGHT(M12,2) -> Q327 | P13: ="Q"&MID(O13,2,1)+1&RIGHT(M12,2) -> Q427 | Q13: ="Q1"&RIGHT(Q12,2) -> Q128 | R13: ="Q"&MID(Q13,2,1)+1&RIGHT(Q12,2) -> Q228 | S13: ="Q"&MID(R13,2,1)+1&RIGHT(Q12,2) -> Q328 | T13: ="Q"&MID(S13,2,1)+1&RIGHT(Q12,2) -> Q428 | U13: ="Q1"&RIGHT(U12,2) -> Q129 | V13: ="Q"&MID(U13,2,1)+1&RIGHT(U12,2) -> Q229 | W13: ="Q"&MID(V13,2,1)+1&RIGHT(U12,2) -> Q329 | X13: ="Q"&MID(W13,2,1)+1&RIGHT(U12,2) -> Q429 | Y13: ="Q1"&RIGHT(Y12,2) -> Q130 | Z13: ="Q"&MID(Y13,2,1)+1&RIGHT(Y12,2) -> Q230 | AA13: ="Q"&MID(Z13,2,1)+1&RIGHT(Y12,2) -> Q330 | AB13: ="Q"&MID(AA13,2,1)+1&RIGHT(Y12,2) -> Q430 | AC13: ="Q1"&RIGHT(AC12,2) -> Q131 | AD13: ="Q"&MID(AC13,2,1)+1&RIGHT(AC12,2) -> Q231 | AE13: ="Q"&MID(AD13,2,1)+1&RIGHT(AC12,2) -> Q331 | AF13: ="Q"&MID(AE13,2,1)+1&RIGHT(AC12,2) -> Q431 | AG13: ="Q1"&RIGHT(AG12,2) -> Q132 | AH13: ="Q"&MID(AG13,2,1)+1&RIGHT(AG12,2) -> Q232 | AI13: ="Q"&MID(AH13,2,1)+1&RIGHT(AG12,2) -> Q332 | AJ13: ="Q"&MID(AI13,2,1)+1&RIGHT(AG12,2) -> Q432 | AK13: Sum HC | AL13: Peak HC | AM13: HC Profile (mini)
B14: Chris | C14: SPG_Platform_Linux | D14: Linux – Program Management/Architectural support | F14: Canada | G14: alloc_MLS_Linux_4 | H14: Incremental - XCHG | M14: 0.2 | N14: 0.5 | O14: 0.5 | P14: 0.5 | Q14: 0.5 | R14: 0.5 | S14: 0.5 | T14: 0.5 | U14: 0.5 | V14: 0.5 | W14: 0.5 | X14: 0.3 | Y14: 0.2 | AE14: 0 | AF14: 0 | AK14: =SUM(I14:AJ14) -> 5.7 | AL14: =MAX(I14:AJ14) -> 0.5
B15: Chris | C15: SPG_Platform_Linux | D15: PreSI emulation | E15: Pre-SI Emulation | F15: Canada | G15: alloc_MLS_Linux_4 | H15: Incremental - XCHG | P15: 0.5 | Q15: 1 | R15: 1.5 | S15: 0.5 | AK15: =SUM(I15:AJ15) -> 3.5 | AL15: =MAX(I15:AJ15) -> 1.5
B16: Chris | C16: SPG_Platform_Linux | D16: NPI support | E16: - Pre-SI Linux Bringup - Linux Bringup (Silicon) with Base kernel | F16: Canada | G16: alloc_MLS_Linux_4 | H16: Incremental - XCHG | Q16: 0.5 | R16: 1 | S16: 2 | T16: 2 | U16: 1.5 | V16: 0.5 | AK16: =SUM(I16:AJ16) -> 7.5 | AL16: =MAX(I16:AJ16) -> 2
B17: Chris | C17: SPG_Platform_Linux | D17: ROCm on APU | E17: - ROCm Bringup on APU - ROCm Feats validation - KFD validation | F17: Canada | G17: alloc_MLS_Linux_4 | H17: Incremental - XCHG | R17: 0.5 | S17: 2 | T17: 1.5 | U17: 1.5 | V17: 1 | W17: 1 | X17: 0.5 | Y17: 0.5 | AK17: =SUM(I17:AJ17) -> 8.5 | AL17: =MAX(I17:AJ17) -> 2
B18: Chris | C18: SPG_Platform_Linux | D18: Linux- BPI | E18: - Build and Packaging - Separate Capitola branch creation. - Build script modifications if any. | F18: China Shanghai | G18: alloc_MLS_Linux_4 | H18: Incremental - XCHG | Q18: 0.5 | R18: 0.5 | S18: 0.5 | T18: 0.5 | U18: 0.5 | V18: 0.5 | W18: 0.5 | X18: 0.3 | Y18: 0.2 | AK18: =SUM(I18:AJ18) -> 4 | AL18: =MAX(I18:AJ18) -> 0.5 | AN18: Talk to Uday to drop the HC
B19: Chris | C19: SPG_Platform_Linux | D19: MM | E19: - H264 and HEVC(Encode, Decode and Transcode) issue debug support. - NVE support | F19: Canada | G19: alloc_MLS_Linux_4 | H19: Incremental - XCHG | Q19: 1 | R19: 1 | S19: 1 | T19: 1 | U19: 1 | V19: 1 | W19: 1 | X19: 0.5 | Y19: 0.5 | AK19: =SUM(I19:AJ19) -> 8 | AL19: =MAX(I19:AJ19) -> 1
B20: Chris | C20: SPG_Platform_Linux | D20: Graphics API | E20: - Mesa, OpenGL 4.6, OpenGL ES 3.2, Vulkan-1.4 (Baremetal issue debug) | F20: Canada | G20: alloc_MLS_Linux_4 | H20: Incremental - XCHG | Q20: 1 | R20: 1 | S20: 1 | T20: 1 | U20: 1 | V20: 1 | W20: 1 | X20: 0.5 | Y20: 0.5 | AK20: =SUM(I20:AJ20) -> 8 | AL20: =MAX(I20:AJ20) -> 1
B21: Chris | C21: SPG_Platform_Linux | D21: Kernel Support | E21: Kernel consultation support | F21: Canada | G21: alloc_MLS_Linux_4 | H21: Incremental - XCHG | S21: 0.5 | T21: 0.5 | U21: 0.5 | V21: 0.5 | W21: 0.5 | X21: 0.3 | Y21: 0.3 | AK21: =SUM(I21:AJ21) -> 3.1 | AL21: =MAX(I21:AJ21) -> 0.5
B22: Chris | C22: SPG_Platform_Linux | D22: Graphics Virtualization - Guest Linux | E22: VirtIO Native Context in DOMU Mesa for virtio-gpu (Vulkan 1.4) Linux kernel virtio-gpu Issue debug and triage in guest DOMU | F22: China Shanghai | G22: alloc_MLS_Linux_3 | H22: Incremental - XCHG | R22: 1 | S22: 1 | T22: 2 | U22: 2 | V22: 2 | W22: 1 | X22: 1 | Y22: 0.5 | AK22: =SUM(I22:AJ22) -> 10.5 | AL22: =MAX(I22:AJ22) -> 2
B23: Chris | C23: SPG_Platform_Linux | D23: VirtIO GPU emulation - Xen/QEMU/Virglrenderer DOM0 (Graphics) | E23: Virtio-gpu in QEMU emulator in DOM0 Blob memory support in QEMU VirtIO GPU command forwarding DRM Renderer API for amdgpu in Virglrenderer in DOM0 AMDGPU DRM API support for guest Mesa Virtio-pci for PVH DOM0 in Xen hypervisor Blob memory support for Xen, dynamic address mapping Virtio support for PVH DOMU and hyper launch in Xen hypervisor CPU fine grain support in Xen hypervisor | F23: China Shanghai | G23: alloc_MLS_Linux_3 | H23: Incremental - XCHG | R23: 1 | S23: 1 | T23: 1.5 | U23: 1.5 | V23: 1.5 | W23: 1 | X23: 1 | Y23: 1 | AK23: =SUM(I23:AJ23) -> 9.5 | AL23: =MAX(I23:AJ23) -> 1.5
B24: Chris | C24: SPG_Platform_Linux | D24: Display Virtualization | E24: Compositor for virtualization use case MPO virtualization GPU recovery (robust context in weston) Multiple display for 4 external displays in one single Ubuntu DOMU Wayland on Linux for virtualization Issue debug and triage for display virtualization | F24: China Shanghai | G24: alloc_MLS_Linux_3 | H24: Incremental - XCHG | R24: 1 | S24: 2 | T24: 2 | U24: 2 | V24: 2 | W24: 1 | X24: 1 | Y24: 1 | AK24: =SUM(I24:AJ24) -> 12 | AL24: =MAX(I24:AJ24) -> 2
B25: Chris | C25: SPG_Platform_Linux | D25: Compute Virtualization - Guest ROCm (virtio-gpu) | E25: ROCR-Runtime, ROCR-CLR development for virtio-gpu Pointer info refactor in ROCR for virtio driver agents Global memory APIs support for virtio driver agents Events APIs refactor for virtio driver agents Enable events wait API in ROCR virtio-gpu CLR adaptation for ROCR VIRTIO backend Host and guest Kernel developments for virtio-gpu Userptr feature in virtio-gpu mapped memory support back end virtio Upper level component virtualization support ROCm debugger for virtio-gpu ROCm tracer for virtio-gpu ROCm profiler for virtio-gpu HIP (runtime) for virtio-gpu | F25: China Shanghai | G25: alloc_MLS_Linux_3 | H25: Incremental - XCHG | R25: 1 | S25: 2 | T25: 2 | U25: 2 | V25: 2 | W25: 1 | X25: 1 | Y25: 0.5 | AK25: =SUM(I25:AJ25) -> 11.5 | AL25: =MAX(I25:AJ25) -> 2
B26: Chris | C26: SPG_Platform_Linux | D26: Compute Virtualization - Guest OpenCL (DOMU) | E26: ROCR Virtio Driver Adaptation for OpenCL2.0 (amdocl) Memory region and pool discovery for OpenCL Queue management adaptation Extend KfdVirtioDriver for OpenCL-specific allocation patterns (scratch, GWS, large buffers) Queue doorbell dispatch latency evaluation and optimization OpenCL Event and Signal Path HSA signal/event latency optimization under polling mode Events wait API integration with OpenCL callbacks and profiling OpenCL Feature Adaptation in DOMU Device capability correct reporting through virtio topology(bus-addressable, IPC, DMA-buf, etc.) DMA-buf / GL interop adaptation via virtio-gpu blob resources Image object support validation (tiling, format queries, read/write/copy paths) C11 atomics, device partitioning, device-side enqueue OCL 2.0 CTS tests debug | F26: China Shanghai | G26: alloc_MLS_Linux_3 | H26: Incremental - XCHG | R26: 1 | S26: 1 | T26: 2 | U26: 2 | V26: 2 | W26: 1 | X26: 1 | Y26: 0.5 | AK26: =SUM(I26:AJ26) -> 10.5 | AL26: =MAX(I26:AJ26) -> 2
B27: Chris | C27: SPG_Platform_Linux | D27: Compute Virtualization - Guest HIP & Mathlib & Tools (DOMU) | E27: Enable and validate ROCm user space HIP, math libraries, and tools on DOMU HIP Runtime, CLR Math libraries ROCblas/hipblas, rocFFT/hipFFT, rocRand, rocprim, rocSPARSE/hipSPARSE, MIOpen, rocSOLVER, hipSOLVER, hipBLASLlt, hipSPARSELt, hipRAND Tools ROCm Profiler, ROCm GDB, AMDSMI, ROCminfo | F27: China Shanghai | G27: alloc_MLS_Linux_3 | H27: Incremental - XCHG | R27: 0.5 | S27: 0.5 | T27: 1 | U27: 1 | V27: 1 | W27: 1 | X27: 0.5 | Y27: 0.5 | AK27: =SUM(I27:AJ27) -> 6 | AL27: =MAX(I27:AJ27) -> 1
B28: Chris | C28: SPG_Platform_Linux | D28: Compute Virtualization - Host KFD multiple context | E28: Linux Kernel KFD multiple contexts: Implement secondary kfd_process-es in kfd module Lifetime management of secondary kfd_process Refactoring sysfs entry for secondary kfd_process Identify secondary kfd_process by id and supportive functions. Support fence and evict for secondary kfd_process Support kfd_mmap for secondary kfd_process Support set_debug_trap ioctl for multiple contexts HIQ and DIQ improvements for multiple contexts Stretch goal (Linux KFD kernel): Upstreaming all the changes SVM support for secondary kfd_process UserPTR support for secondary kfd_process Libhsakmt (thunk) multiple context developments Primary context validation Secondary context support KFDtests for secondary context | F28: China Shanghai | G28: alloc_MLS_Linux_3 | H28: Incremental - XCHG | R28: 0.5 | S28: 1 | T28: 1 | U28: 1 | V28: 1 | W28: 1 | X28: 0.5 | Y28: 0.5 | AK28: =SUM(I28:AJ28) -> 6.5 | AL28: =MAX(I28:AJ28) -> 1
B29: Chris | C29: SPG_Platform_Linux | D29: VirtIO GPU emulation - Xen/QEMU/Virglrenderer DOM0 (Compute) | E29: Virglrenderer virtualized thunk developments for virtio-gpu Virglrenderer thunk API forwarding for virtio-gpu Multi KFD context feature modifications in virglrenderer QEMU, hypervisor development for virtio-gpu QEMU API forwarding features for HIP APIs Hypervisor, QEMU memory managements features for HIP APIs | F29: China Shanghai | G29: alloc_MLS_Linux_3 | H29: Incremental - XCHG | R29: 1 | S29: 1 | T29: 1.5 | U29: 1.5 | V29: 1.5 | W29: 1 | X29: 1 | Y29: 1 | AK29: =SUM(I29:AJ29) -> 9.5 | AL29: =MAX(I29:AJ29) -> 1.5
B30: Chris | C30: SPG_Platform_Linux | D30: DRM render node for ROCm virtualization | E30: DRM SVM for AMDGPU development which is required by latest unified KFD/KGD stack Initialization - Initialize drm_gpusvm during VM init IOCTL Interface - Add IOCTL to create SVM range and map system pages to VM Page Fault Handling - Retry page fault recovery by creating or finding SVM range and mapping pages Memory Invalidation - Implement amdgpu_svm_invalidate via MMU notifier to unmap SVM range and add to garbage collector Page Migration & Prefetch - Implement page migration with SVM range BO, drm_pagemap ops, amdgpu_migrate.c callbacks, prefetch IOCTL, and migration policy in fault handler based on preferred location Memory Eviction - Implement TTM eviction of SVM range BO to system memory under VRAM pressure using fence and evict worker Legacy Replacement - Optionally replace amdgpu_gem_userptr_ioctl with SVM IOCTL | F30: China Shanghai | G30: alloc_MLS_Linux_3 | H30: Incremental - XCHG | R30: 0.5 | S30: 0.5 | T30: 1 | U30: 1 | V30: 1 | W30: 1 | X30: 0.5 | Y30: 0.5 | AK30: =SUM(I30:AJ30) -> 6 | AL30: =MAX(I30:AJ30) -> 1
B31: Chris | C31: SPG_Platform_Linux | D31: Cross functional team support/ Integrated Delivery Support | E31: Providing debugging and feature support for other G&E software teams, including ATG, security, and display. | F31: China Shanghai | G31: alloc_MLS_Linux_3 | H31: Incremental - XCHG | R31: 1 | S31: 1 | T31: 2 | U31: 2 | V31: 2 | W31: 1 | X31: 1 | Y31: 1 | AK31: =SUM(I31:AJ31) -> 11 | AL31: =MAX(I31:AJ31) -> 2
B32: Chris | C32: SPG_Platform_Linux | D32: GPU recovery virtualization | E32: GPU recovery for virtio-gpu | F32: China Shanghai | G32: alloc_MLS_Linux_3 | H32: Incremental - XCHG | R32: 0 | S32: 0.5 | T32: 0.5 | U32: 1 | V32: 1 | W32: 1 | X32: 1 | Y32: 1 | AK32: =SUM(I32:AJ32) -> 6 | AL32: =MAX(I32:AJ32) -> 1
B33: Chris | C33: SPG_Platform_Linux | D33: Power Management Virtualization - Guest | E33: Linux DOMU S3/reboot support for suspend and resume | F33: China Shanghai | G33: alloc_MLS_Linux_3 | H33: Incremental - XCHG | R33: 0.5 | S33: 0.5 | T33: 1 | U33: 1 | V33: 1 | W33: 1 | X33: 0.5 | Y33: 0.5 | AK33: =SUM(I33:AJ33) -> 6 | AL33: =MAX(I33:AJ33) -> 1
B34: Chris | C34: SPG_Platform_Linux | D34: Linux - Solution Architect team | E34: Provide Linux virtualization solution architecture, technical alignment, and cross-component integration support. | F34: China Shanghai | G34: alloc_MLS_Linux_3 | H34: Incremental - XCHG | L34: 0.5 | M34: 0.5 | N34: 0.5 | O34: 0.5 | P34: 0.5 | Q34: 0.5 | R34: 0.5 | S34: 0.5 | T34: 0.5 | U34: 0.5 | V34: 0.5 | W34: 0.5 | X34: 0.5 | Y34: 0.5 | AK34: =SUM(I34:AJ34) -> 7 | AL34: =MAX(I34:AJ34) -> 0.5
B35: Chris | C35: SPG_Platform_Linux | D35: Linux IQE | E35: - Validation support during bringup(silicon) - Feature Validation for ROCm/GFX/Xen/ML frameworks/tools/MM/Power/Display - Weekly integration Validation to maintain stable baseline - Full cycle test for each release | F35: China Shanghai | G35: alloc_MLS_Linux_1 | H35: Incremental - XCHG | S35: 2 | T35: 4 | U35: 5 | V35: 5 | W35: 4 | X35: 2 | Y35: 2 | AK35: =SUM(I35:AJ35) -> 24 | AL35: =MAX(I35:AJ35) -> 5
B36: Chris | C36: SPG_Platform_Linux | D36: AMD SMI | E36: AMD SMI support for Baremetal | F36: USA | G36: alloc_MLS_Linux_1 | H36: Incremental - XCHG | R36: 0.1 | S36: 0.2 | T36: 0.2 | U36: 0.1 | V36: 0.1 | W36: 0.1 | X36: 0.1 | Y36: 0.1 | AK36: =SUM(I36:AJ36) -> 1 | AL36: =MAX(I36:AJ36) -> 0.2
AK37: =SUM(I37:AJ37) -> 0 | AL37: =MAX(I37:AJ37) -> 0
AK38: =SUM(I38:AJ38) -> 0 | AL38: =MAX(I38:AJ38) -> 0
AK39: =SUM(I39:AJ39) -> 0 | AL39: =MAX(I39:AJ39) -> 0
AK40: =SUM(I40:AJ40) -> 0 | AL40: =MAX(I40:AJ40) -> 0
AK41: =SUM(I41:AJ41) -> 0 | AL41: =MAX(I41:AJ41) -> 0
AK42: =SUM(I42:AJ42) -> 0 | AL42: =MAX(I42:AJ42) -> 0
...

Sheet Capitola v1.0 r2 (EPD)
D1: Architecture / Planning | E1: Solution architect on-board (0.5 HC), PM/arch support starting (0.2 HC). Pre-program alignment.
D2: Pre-SI Ramp | E2: Program management, solution arch at steady 0.5. Pre-SI emulation kicks in Q4 FY27.
D3: Silicon Bringup (NPI) | E3: Major ramp. NPI support, Pre-SI emulation, all development teams start. HC jumps from 5.5 → 18 → 25 in Q128→Q228→Q328.
D4: Peak Development | E4: All virtualization, ROCm, graphics, IQE at full strength. Peak HC = 31.6 in Q1 FY29
D5: Integration / Validation | E5: HC winds down from 30 → 22 → 15. Feature complete, validation cycles.
D6: Sustaining / Long Tail | E6: 13.3 HC in Q4 FY29, tapering to ~0 by end of FY30. Maintenance and customer use-case support.
A9: =_xlfn.XLOOKUP(AM10,Status,statusnote,"",0,1) -> Sizing is OPEN. Please UPDATE your estimates for your teams in this sheet. Also UPDATE the scope, assumptions and risks in the Assumptions tab. | AM9: Status
A10: Capitola v1.0 | D10: Notes: BU - BU - AECG • | AM10: In Progress
A11: Last Updated | C11: 46134 | D11: Schedule Milestones>>
D12: Resource Allocation | I12: 2026 | M12: =I12+1 -> 2027 | Q12: =M12+1 -> 2028 | U12: =Q12+1 -> 2029 | Y12: =U12+1 -> 2030 | AC12: =Y12+1 -> 2031 | AG12: =AC12+1 -> 2032 | AK12: =SUBTOTAL(9,AK14:AK16) -> 19 | AL12: =SUBTOTAL(9,AL14:AL16) -> 4.5
A13: Category | B13: Leader | C13: Top Level Team | D13: Function / Contact | E13: Scope of work | F13: Location | G13: Allocation File | H13: HC Type | I13: ="Q1"&RIGHT(I12,2) -> Q126 | J13: ="Q"&MID(I13,2,1)+1&RIGHT(I12,2) -> Q226 | K13: ="Q"&MID(J13,2,1)+1&RIGHT(I12,2) -> Q326 | L13: ="Q"&MID(K13,2,1)+1&RIGHT(I12,2) -> Q426 | M13: ="Q1"&RIGHT(M12,2) -> Q127 | N13: ="Q"&MID(M13,2,1)+1&RIGHT(M12,2) -> Q227 | O13: ="Q"&MID(N13,2,1)+1&RIGHT(M12,2) -> Q327 | P13: ="Q"&MID(O13,2,1)+1&RIGHT(M12,2) -> Q427 | Q13: ="Q1"&RIGHT(Q12,2) -> Q128 | R13: ="Q"&MID(Q13,2,1)+1&RIGHT(Q12,2) -> Q228 | S13: ="Q"&MID(R13,2,1)+1&RIGHT(Q12,2) -> Q328 | T13: ="Q"&MID(S13,2,1)+1&RIGHT(Q12,2) -> Q428 | U13: ="Q1"&RIGHT(U12,2) -> Q129 | V13: ="Q"&MID(U13,2,1)+1&RIGHT(U12,2) -> Q229 | W13: ="Q"&MID(V13,2,1)+1&RIGHT(U12,2) -> Q329 | X13: ="Q"&MID(W13,2,1)+1&RIGHT(U12,2) -> Q429 | Y13: ="Q1"&RIGHT(Y12,2) -> Q130 | Z13: ="Q"&MID(Y13,2,1)+1&RIGHT(Y12,2) -> Q230 | AA13: ="Q"&MID(Z13,2,1)+1&RIGHT(Y12,2) -> Q330 | AB13: ="Q"&MID(AA13,2,1)+1&RIGHT(Y12,2) -> Q430 | AC13: ="Q1"&RIGHT(AC12,2) -> Q131 | AD13: ="Q"&MID(AC13,2,1)+1&RIGHT(AC12,2) -> Q231 | AE13: ="Q"&MID(AD13,2,1)+1&RIGHT(AC12,2) -> Q331 | AF13: ="Q"&MID(AE13,2,1)+1&RIGHT(AC12,2) -> Q431 | AG13: ="Q1"&RIGHT(AG12,2) -> Q132 | AH13: ="Q"&MID(AG13,2,1)+1&RIGHT(AG12,2) -> Q232 | AI13: ="Q"&MID(AH13,2,1)+1&RIGHT(AG12,2) -> Q332 | AJ13: ="Q"&MID(AI13,2,1)+1&RIGHT(AG12,2) -> Q432 | AK13: Sum HC | AL13: Peak HC | AM13: HC Profile (mini)
B14: Chris | C14: SPG_Platform_Linux | D14: PreSI emulation | E14: Pre-SI Emulation | F14: Canada | G14: alloc_MLS_Linux_4 | H14: Incremental - XCHG | P14: 1 | Q14: 1 | R14: 1.5 | S14: 0.5 | AK14: =SUM(I14:AJ14) -> 4 | AL14: =MAX(I14:AJ14) -> 1.5
B15: Chris | C15: SPG_Platform_Linux | D15: NPI support | E15: - Pre-SI Linux Bringup - Linux Bringup (Silicon) with Base kernel | F15: Canada | G15: alloc_MLS_Linux_4 | H15: Incremental - XCHG | Q15: 0.5 | R15: 1 | S15: 2 | T15: 1.5 | U15: 1.5 | V15: 0.5 | AK15: =SUM(I15:AJ15) -> 7 | AL15: =MAX(I15:AJ15) -> 2
B16: Chris | C16: SPG_Platform_Linux | D16: Graphics API | E16: - Mesa, OpenGL 4.6, OpenGL ES 3.2, Vulkan-1.4 (Baremetal issue debug) | F16: Canada | G16: alloc_MLS_Linux_4 | H16: Incremental - XCHG | Q16: 1 | R16: 1 | S16: 1 | T16: 1 | U16: 1 | V16: 1 | W16: 1 | X16: 0.5 | Y16: 0.5 | AK16: =SUM(I16:AJ16) -> 8 | AL16: =MAX(I16:AJ16) -> 1
B17: Chris | C17: SPG_Platform_Linux | D17: Kernel Support | E17: Kernel consultation support | F17: Canada | G17: alloc_MLS_Linux_4 | H17: Incremental - XCHG | T17: 0.5 | U17: 0.5 | V17: 0.5 | W17: 0.5 | X17: 0.3 | Y17: 0.3 | AK17: =SUM(I17:AJ17) -> 2.6 | AL17: =MAX(I17:AJ17) -> 0.5
A19: Terms of Reference | G19: HC Profile | H19: Existing - AOP | I19: {=SUMPRODUCT(SUBTOTAL(9,OFFSET(#REF!,ROW(I$14:I$18)-ROW(#REF!),)),--($H$14:$H$18=$H19))} -> #REF! | J19: {=SUMPRODUCT(SUBTOTAL(9,OFFSET(#REF!,ROW(J$14:J$18)-ROW(#REF!),)),--($H$14:$H$18=$H19))} -> #REF! | K19: {=SUMPRODUCT(SUBTOTAL(9,OFFSET(#REF!,ROW(K$14:K$18)-ROW(#REF!),)),--($H$14:$H$18=$H19))} -> #REF! | L19: {=SUMPRODUCT(SUBTOTAL(9,OFFSET(#REF!,ROW(L$14:L$18)-ROW(#REF!),)),--($H$14:$H$18=$H19))} -> #REF! | M19: {=SUMPRODUCT(SUBTOTAL(9,OFFSET(#REF!,ROW(M$14:M$18)-ROW(#REF!),)),--($H$14:$H$18=$H19))} -> #REF! | N19: {=SUMPRODUCT(SUBTOTAL(9,OFFSET(#REF!,ROW(N$14:N$18)-ROW(#REF!),)),--($H$14:$H$18=$H19))} -> #REF! | O19: {=SUMPRODUCT(SUBTOTAL(9,OFFSET(#REF!,ROW(O$14:O$18)-ROW(#REF!),)),--($H$14:$H$18=$H19))} -> #REF! | P19: {=SUMPRODUCT(SUBTOTAL(9,OFFSET(#REF!,ROW(P$14:P$18)-ROW(#REF!),)),--($H$14:$H$18=$H19))} -> #REF! | ... AK19: {=SUMPRODUCT(SUBTOTAL(9,OFFSET(#REF!,ROW(AK$14:AK$18)-ROW(#REF!),)),--($H$14:$H$18=$H19))} -> #REF! | AL19: =MAX(I19:AJ19) -> #REF!
A20: Existing - AOP | C20: Existing resources already hired, AOP funded on a permanent basis | H20: Incremental - XCHG | I20: {=SUMPRODUCT(SUBTOTAL(9,OFFSET(#REF!,ROW(I$14:I$18)-ROW(#REF!),)),--($H$14:$H$18=$H20))} -> #REF! | J20: {=SUMPRODUCT(SUBTOTAL(9,OFFSET(#REF!,ROW(J$14:J$18)-ROW(#REF!),)),--($H$14:$H$18=$H20))} -> #REF! | K20: {=SUMPRODUCT(SUBTOTAL(9,OFFSET(#REF!,ROW(K$14:K$18)-ROW(#REF!),)),--($H$14:$H$18=$H20))} -> #REF! | L20: {=SUMPRODUCT(SUBTOTAL(9,OFFSET(#REF!,ROW(L$14:L$18)-ROW(#REF!),)),--($H$14:$H$18=$H20))} -> #REF! | M20: {=SUMPRODUCT(SUBTOTAL(9,OFFSET(#REF!,ROW(M$14:M$18)-ROW(#REF!),)),--($H$14:$H$18=$H20))} -> #REF! | N20: {=SUMPRODUCT(SUBTOTAL(9,OFFSET(#REF!,ROW(N$14:N$18)-ROW(#REF!),)),--($H$14:$H$18=$H20))} -> #REF! | O20: {=SUMPRODUCT(SUBTOTAL(9,OFFSET(#REF!,ROW(O$14:O$18)-ROW(#REF!),)),--($H$14:$H$18=$H20))} -> #REF! | P20: {=SUMPRODUCT(SUBTOTAL(9,OFFSET(#REF!,ROW(P$14:P$18)-ROW(#REF!),)),--($H$14:$H$18=$H20))} -> #REF! | ... AK20: {=SUMPRODUCT(SUBTOTAL(9,OFFSET(#REF!,ROW(AK$14:AK$18)-ROW(#REF!),)),--($H$14:$H$18=$H20))} -> #REF! | AL20: =MAX(I20:AJ20) -> #REF!
C21: e.g. HC_REG, HC_TEM, HC_COO, HC_CON, Commit - Co-Op | H21: Grand Total | I21: =SUM(I19:I20) -> #REF! | J21: =SUM(J19:J20) -> #REF! | K21: =SUM(K19:K20) -> #REF! | L21: =SUM(L19:L20) -> #REF! | M21: =SUM(M19:M20) -> #REF! | N21: =SUM(N19:N20) -> #REF! | O21: =SUM(O19:O20) -> #REF! | P21: =SUM(P19:P20) -> #REF! | ... AK21: =SUM(AK19:AK20) -> #REF! | AL21: =MAX(I21:AJ21) -> #REF!
AC22: {=SUMPRODUCT(SUBTOTAL(9,OFFSET(#REF!,ROW(AC$14:AC$18)-ROW(#REF!),)),--($H$14:$H$18=$H19),#REF!)} -> #REF! | AD22: {=SUMPRODUCT(SUBTOTAL(9,OFFSET(#REF!,ROW(AD$14:AD$18)-ROW(#REF!),)),--($H$14:$H$18=$H19),#REF!)} -> #REF! | AE22: {=SUMPRODUCT(SUBTOTAL(9,OFFSET(#REF!,ROW(AE$14:AE$18)-ROW(#REF!),)),--($H$14:$H$18=$H19),#REF!)} -> #REF! | AF22: {=SUMPRODUCT(SUBTOTAL(9,OFFSET(#REF!,ROW(AF$14:AF$18)-ROW(#REF!),)),--($H$14:$H$18=$H19),#REF!)} -> #REF! | AG22: {=SUMPRODUCT(SUBTOTAL(9,OFFSET(#REF!,ROW(AG$14:AG$18)-ROW(#REF!),)),--($H$14:$H$18=$H19),#REF!)} -> #REF! | AH22: {=SUMPRODUCT(SUBTOTAL(9,OFFSET(#REF!,ROW(AH$14:AH$18)-ROW(#REF!),)),--($H$14:$H$18=$H19),#REF!)} -> #REF! | AI22: {=SUMPRODUCT(SUBTOTAL(9,OFFSET(#REF!,ROW(AI$14:AI$18)-ROW(#REF!),)),--($H$14:$H$18=$H19),#REF!)} -> #REF! | AJ22: {=SUMPRODUCT(SUBTOTAL(9,OFFSET(#REF!,ROW(AJ$14:AJ$18)-ROW(#REF!),)),--($H$14:$H$18=$H19),#REF!)} -> #REF!
A23: Incremental - XCHG | C23: Incremental resources request for HC, XCHG funded (typical) on a temporary basis | AC23: {=SUMPRODUCT(SUBTOTAL(9,OFFSET(#REF!,ROW(AC$14:AC$18)-ROW(#REF!),)),--($H$14:$H$18=$H20),#REF!)} -> #REF! | AD23: {=SUMPRODUCT(SUBTOTAL(9,OFFSET(#REF!,ROW(AD$14:AD$18)-ROW(#REF!),)),--($H$14:$H$18=$H20),#REF!)} -> #REF! | AE23: {=SUMPRODUCT(SUBTOTAL(9,OFFSET(#REF!,ROW(AE$14:AE$18)-ROW(#REF!),)),--($H$14:$H$18=$H20),#REF!)} -> #REF! | AF23: {=SUMPRODUCT(SUBTOTAL(9,OFFSET(#REF!,ROW(AF$14:AF$18)-ROW(#REF!),)),--($H$14:$H$18=$H20),#REF!)} -> #REF! | AG23: {=SUMPRODUCT(SUBTOTAL(9,OFFSET(#REF!,ROW(AG$14:AG$18)-ROW(#REF!),)),--($H$14:$H$18=$H20),#REF!)} -> #REF! | AH23: {=SUMPRODUCT(SUBTOTAL(9,OFFSET(#REF!,ROW(AH$14:AH$18)-ROW(#REF!),)),--($H$14:$H$18=$H20),#REF!)} -> #REF! | AI23: {=SUMPRODUCT(SUBTOTAL(9,OFFSET(#REF!,ROW(AI$14:AI$18)-ROW(#REF!),)),--($H$14:$H$18=$H20),#REF!)} -> #REF! | AJ23: {=SUMPRODUCT(SUBTOTAL(9,OFFSET(#REF!,ROW(AJ$14:AJ$18)-ROW(#REF!),)),--($H$14:$H$18=$H20),#REF!)} -> #REF!
C24: e.g. Gaps, Non-HC - SPW, Outside Services (OSS) | AC24: =SUM(AC22:AC23) -> #REF! | AD24: =SUM(AD22:AD23) -> #REF! | AE24: =SUM(AE22:AE23) -> #REF! | AF24: =SUM(AF22:AF23) -> #REF! | AG24: =SUM(AG22:AG23) -> #REF! | AH24: =SUM(AH22:AH23) -> #REF! | AI24: =SUM(AI22:AI23) -> #REF! | AJ24: =SUM(AJ22:AJ23) -> #REF!
AC25: =AC20-AB20 -> #REF! | AD25: =AD20-AC20 -> #REF! | AE25: =AE20-AD20 -> #REF! | AF25: =AF20-AE20 -> #REF! | AG25: =AG20-AF20 -> #REF! | AH25: =AH20-AG20 -> #REF! | AI25: =AI20-AH20 -> #REF! | AJ25: =AJ20-AI20 -> #REF!
AC26: NC - No change | AD26: NC - No change | AE26: NC - No change | AF26: NC - No change | AG26: NC - No change | AH26: NC - No change | AI26: NC - No change | AJ26: NC - No change
AC27: =_xlfn.XLOOKUP(AC$26,Scenarios,'Ramp Scenarios'!$C$3:$C$11)*SUM(AC20:AC20)-SUM(AC20:AC20) -> #REF! | AD27: =_xlfn.XLOOKUP(AD$26,Scenarios,'Ramp Scenarios'!$C$3:$C$11)*SUM(AD20:AD20)-SUM(AD20:AD20) -> #REF! | AE27: =_xlfn.XLOOKUP(AE$26,Scenarios,'Ramp Scenarios'!$C$3:$C$11)*SUM(AE20:AE20)-SUM(AE20:AE20) -> #REF! | AF27: =_xlfn.XLOOKUP(AF$26,Scenarios,'Ramp Scenarios'!$C$3:$C$11)*SUM(AF20:AF20)-SUM(AF20:AF20) -> #REF! | AG27: =_xlfn.XLOOKUP(AG$26,Scenarios,'Ramp Scenarios'!$C$3:$C$11)*SUM(AG20:AG20)-SUM(AG20:AG20) -> #REF! | AH27: =_xlfn.XLOOKUP(AH$26,Scenarios,'Ramp Scenarios'!$C$3:$C$11)*SUM(AH20:AH20)-SUM(AH20:AH20) -> #REF! | AI27: =_xlfn.XLOOKUP(AI$26,Scenarios,'Ramp Scenarios'!$C$3:$C$11)*SUM(AI20:AI20)-SUM(AI20:AI20) -> #REF! | AJ27: =_xlfn.XLOOKUP(AJ$26,Scenarios,'Ramp Scenarios'!$C$3:$C$11)*SUM(AJ20:AJ20)-SUM(AJ20:AJ20) -> #REF!
AC28: =(AC23)*_xlfn.XLOOKUP(AC26,Scenarios,'Ramp Scenarios'!$C$3:$C$11) -> #REF! | AD28: =(AD23)*_xlfn.XLOOKUP(AD26,Scenarios,'Ramp Scenarios'!$C$3:$C$11) -> #REF! | AE28: =(AE23)*_xlfn.XLOOKUP(AE26,Scenarios,'Ramp Scenarios'!$C$3:$C$11) -> #REF! | AF28: =(AF23)*_xlfn.XLOOKUP(AF26,Scenarios,'Ramp Scenarios'!$C$3:$C$11) -> #REF! | AG28: =(AG23)*_xlfn.XLOOKUP(AG26,Scenarios,'Ramp Scenarios'!$C$3:$C$11) -> #REF! | AH28: =(AH23)*_xlfn.XLOOKUP(AH26,Scenarios,'Ramp Scenarios'!$C$3:$C$11) -> #REF! | AI28: =(AI23)*_xlfn.XLOOKUP(AI26,Scenarios,'Ramp Scenarios'!$C$3:$C$11) -> #REF! | AJ28: =(AJ23)*_xlfn.XLOOKUP(AJ26,Scenarios,'Ramp Scenarios'!$C$3:$C$11) -> #REF!
AC29: =AC28+AC22 -> #REF! | AD29: =AD28+AD22 -> #REF! | AE29: =AE28+AE22 -> #REF! | AF29: =AF28+AF22 -> #REF! | AG29: =AG28+AG22 -> #REF! | AH29: =AH28+AH22 -> #REF! | AI29: =AI28+AI22 -> #REF! | AJ29: =AJ28+AJ22 -> #REF!

Sheet Capitola v1.0 r2 (PAVS)
D1: Architecture / Planning | E1: Solution architect on-board (0.5 HC), PM/arch support starting (0.2 HC). Pre-program alignment.
D2: Pre-SI Ramp | E2: Program management, solution arch at steady 0.5. Pre-SI emulation kicks in Q4 FY27.
D3: Silicon Bringup (NPI) | E3: Major ramp. NPI support, Pre-SI emulation, all development teams start. HC jumps from 5.5 → 18 → 25 in Q128→Q228→Q328.
D4: Peak Development | E4: All virtualization, ROCm, graphics, IQE at full strength. Peak HC = 31.6 in Q1 FY29
D5: Integration / Validation | E5: HC winds down from 30 → 22 → 15. Feature complete, validation cycles.
D6: Sustaining / Long Tail | E6: 13.3 HC in Q4 FY29, tapering to ~0 by end of FY30. Maintenance and customer use-case support.
A9: =_xlfn.XLOOKUP(AM10,Status,statusnote,"",0,1) -> Sizing is OPEN. Please UPDATE your estimates for your teams in this sheet. Also UPDATE the scope, assumptions and risks in the Assumptions tab. | AM9: Status
A10: Capitola v1.0 | D10: Notes: BU - BU - AECG • | AM10: In Progress
A11: Last Updated | C11: 46134 | D11: Schedule Milestones>>
D12: Resource Allocation | I12: 2026 | M12: =I12+1 -> 2027 | Q12: =M12+1 -> 2028 | U12: =Q12+1 -> 2029 | Y12: =U12+1 -> 2030 | AC12: =Y12+1 -> 2031 | AG12: =AC12+1 -> 2032 | AK12: =SUBTOTAL(9,AK14:AK67) -> 219.7 | AL12: =SUBTOTAL(9,AL14:AL67) -> 36.2
A13: Category | B13: Leader | C13: Top Level Team | D13: Function / Contact | E13: Scope of work | F13: Location | G13: Allocation File | H13: HC Type | I13: ="Q1"&RIGHT(I12,2) -> Q126 | J13: ="Q"&MID(I13,2,1)+1&RIGHT(I12,2) -> Q226 | K13: ="Q"&MID(J13,2,1)+1&RIGHT(I12,2) -> Q326 | L13: ="Q"&MID(K13,2,1)+1&RIGHT(I12,2) -> Q426 | M13: ="Q1"&RIGHT(M12,2) -> Q127 | N13: ="Q"&MID(M13,2,1)+1&RIGHT(M12,2) -> Q227 | O13: ="Q"&MID(N13,2,1)+1&RIGHT(M12,2) -> Q327 | P13: ="Q"&MID(O13,2,1)+1&RIGHT(M12,2) -> Q427 | Q13: ="Q1"&RIGHT(Q12,2) -> Q128 | R13: ="Q"&MID(Q13,2,1)+1&RIGHT(Q12,2) -> Q228 | S13: ="Q"&MID(R13,2,1)+1&RIGHT(Q12,2) -> Q328 | T13: ="Q"&MID(S13,2,1)+1&RIGHT(Q12,2) -> Q428 | U13: ="Q1"&RIGHT(U12,2) -> Q129 | V13: ="Q"&MID(U13,2,1)+1&RIGHT(U12,2) -> Q229 | W13: ="Q"&MID(V13,2,1)+1&RIGHT(U12,2) -> Q329 | X13: ="Q"&MID(W13,2,1)+1&RIGHT(U12,2) -> Q429 | Y13: ="Q1"&RIGHT(Y12,2) -> Q130 | Z13: ="Q"&MID(Y13,2,1)+1&RIGHT(Y12,2) -> Q230 | AA13: ="Q"&MID(Z13,2,1)+1&RIGHT(Y12,2) -> Q330 | AB13: ="Q"&MID(AA13,2,1)+1&RIGHT(Y12,2) -> Q430 | AC13: ="Q1"&RIGHT(AC12,2) -> Q131 | AD13: ="Q"&MID(AC13,2,1)+1&RIGHT(AC12,2) -> Q231 | AE13: ="Q"&MID(AD13,2,1)+1&RIGHT(AC12,2) -> Q331 | AF13: ="Q"&MID(AE13,2,1)+1&RIGHT(AC12,2) -> Q431 | AG13: ="Q1"&RIGHT(AG12,2) -> Q132 | AH13: ="Q"&MID(AG13,2,1)+1&RIGHT(AG12,2) -> Q232 | AI13: ="Q"&MID(AH13,2,1)+1&RIGHT(AG12,2) -> Q332 | AJ13: ="Q"&MID(AI13,2,1)+1&RIGHT(AG12,2) -> Q432 | AK13: Sum HC | AL13: Peak HC | AM13: HC Profile (mini)
B14: Chris | C14: SPG_Platform_Linux | D14: Linux – Program Management/Architectural support | F14: Canada | G14: alloc_MLS_Linux_4 | H14: Incremental - XCHG | M14: 0.2 | N14: 0.5 | O14: 0.5 | P14: 0.5 | Q14: 0.5 | R14: 0.5 | S14: 0.5 | T14: 0.5 | U14: 0.5 | V14: 0.5 | W14: 0.5 | X14: 0.3 | Y14: 0.2 | AE14: 0 | AF14: 0 | AK14: =SUM(I14:AJ14) -> 5.7 | AL14: =MAX(I14:AJ14) -> 0.5
B15: Chris | C15: SPG_Platform_Linux | D15: ROCm on APU | E15: - ROCm Bringup on APU - ROCm Feats validation - KFD validation | F15: Canada | G15: alloc_MLS_Linux_4 | H15: Incremental - XCHG | R15: 0.5 | S15: 1.5 | T15: 1.5 | U15: 1.5 | V15: 1 | W15: 1 | X15: 0.5 | Y15: 0.5 | AK15: =SUM(I15:AJ15) -> 8 | AL15: =MAX(I15:AJ15) -> 1.5
B16: Chris | C16: SPG_Platform_Linux | D16: Linux- BPI | E16: - Build and Packaging - Separate Capitola branch creation. - Build script modifications if any. | F16: China Shanghai | G16: alloc_MLS_Linux_4 | H16: Incremental - XCHG | Q16: 0.5 | R16: 0.5 | S16: 0.5 | T16: 0.5 | U16: 0.5 | V16: 0.5 | W16: 0.5 | X16: 0.3 | Y16: 0.2 | AK16: =SUM(I16:AJ16) -> 4 | AL16: =MAX(I16:AJ16) -> 0.5
B17: Chris | C17: SPG_Platform_Linux | D17: MM | E17: - H264 and HEVC(Encode, Decode and Transcode) issue debug support. - NVE support | F17: Canada | G17: alloc_MLS_Linux_4 | H17: Incremental - XCHG | Q17: 1 | R17: 1 | S17: 1 | T17: 1 | U17: 1 | V17: 1 | W17: 1 | X17: 0.5 | Y17: 0.5 | AK17: =SUM(I17:AJ17) -> 8 | AL17: =MAX(I17:AJ17) -> 1
B18: Chris | C18: SPG_Platform_Linux | D18: Graphics Virtualization - Guest Linux | E18: VirtIO Native Context in DOMU Mesa for virtio-gpu (Vulkan 1.4) Linux kernel virtio-gpu Issue debug and triage in guest DOMU | F18: China Shanghai | G18: alloc_MLS_Linux_3 | H18: Incremental - XCHG | R18: 1 | S18: 1 | T18: 2 | U18: 2 | V18: 2 | W18: 1 | X18: 1 | Y18: 0.5 | AK18: =SUM(I18:AJ18) -> 10.5 | AL18: =MAX(I18:AJ18) -> 2
B19: Chris | C19: SPG_Platform_Linux | D19: VirtIO GPU emulation - Xen/QEMU/Virglrenderer DOM0 (Graphics) | E19: Virtio-gpu in QEMU emulator in DOM0 Blob memory support in QEMU VirtIO GPU command forwarding DRM Renderer API for amdgpu in Virglrenderer in DOM0 AMDGPU DRM API support for guest Mesa Virtio-pci for PVH DOM0 in Xen hypervisor Blob memory support for Xen, dynamic address mapping Virtio support for PVH DOMU and hyper launch in Xen hypervisor CPU fine grain support in Xen hypervisor | F19: China Shanghai | G19: alloc_MLS_Linux_3 | H19: Incremental - XCHG | R19: 1 | S19: 1 | T19: 1.5 | U19: 1.5 | V19: 1.5 | W19: 1 | X19: 1 | Y19: 1 | AK19: =SUM(I19:AJ19) -> 9.5 | AL19: =MAX(I19:AJ19) -> 1.5
B20: Chris | C20: SPG_Platform_Linux | D20: VirtIO GPU emulation - Xen/QEMU/Virglrenderer DOM0 (Graphics - Windows) | E20: Develop the blob memory and virtio-gpu based functions for windows domU Integrate the dynamic mapping function for windows domU | F20: China Shanghai | G20: alloc_MLS_Linux_3 | H20: Incremental - XCHG | R20: 1 | S20: 1 | T20: 2 | U20: 2 | V20: 2 | W20: 2 | X20: 1 | Y20: 1 | AK20: =SUM(I20:AJ20) -> 12 | AL20: =MAX(I20:AJ20) -> 2
B21: Chris | C21: SPG_Platform_Linux | D21: Display Virtualization | E21: Compositor for virtualization use case MPO virtualization GPU recovery (robust context in weston) Multiple display for 4 external displays in one single Ubuntu DOMU Wayland on Linux for virtualization Issue debug and triage for display virtualization | F21: China Shanghai | G21: alloc_MLS_Linux_3 | H21: Incremental - XCHG | R21: 1 | S21: 2 | T21: 2 | U21: 2 | V21: 2 | W21: 1 | X21: 1 | Y21: 1 | AK21: =SUM(I21:AJ21) -> 12 | AL21: =MAX(I21:AJ21) -> 2
B22: Chris | C22: SPG_Platform_Linux | D22: Display Virtualization (Windows) | E22: Compositor for virtualization use case Multiple display for 4 external displays in one single Windows DOMU EDID emulation for Windows DOMU Display hot-plug for Windows DOMU DPMST for Windows DOMU Enable display KMS function for windows DOMU | F22: China Shanghai | G22: alloc_MLS_Linux_3 | H22: Incremental - XCHG | R22: 0.5 | S22: 1 | T22: 1 | U22: 1 | V22: 1 | W22: 1 | X22: 1 | Y22: 0.5 | AK22: =SUM(I22:AJ22) -> 7 | AL22: =MAX(I22:AJ22) -> 1
B23: Chris | C23: SPG_Platform_Linux | D23: Graphics Virtualization - Guest Windows KMD | E23: Windows VirtIO GPU kernel Develop the new WDDM driver for VirtIO GPU Add viogpu3d driver under viogpu module | F23: China Shanghai | G23: alloc_MLS_Linux_3 | R23: 1 | S23: 1 | T23: 2 | U23: 2 | V23: 2 | W23: 2 | X23: 1 | Y23: 1 | AK23: =SUM(I23:AJ23) -> 12 | AL23: =MAX(I23:AJ23) -> 2
B24: Chris | C24: SPG_Platform_Linux | D24: Graphics Virtualization - Guest Windows UMD (Virgl) | E24: Develop GDI interfaces (virtio-gpu) for gallium winsys to talk with windows gdi32.ddl Integrate virgl gallium driver with windows gdi (virtio-gpu) winsys APIs Enable frontend and target for d3dumd for the backend as virgl Enable frontend and target for wgl for the backend as virgl | F24: China Shanghai | G24: alloc_MLS_Linux_3 | R24: 0.5 | S24: 1 | T24: 1 | U24: 1 | V24: 1 | W24: 1 | X24: 1 | Y24: 0.5 | AK24: =SUM(I24:AJ24) -> 7 | AL24: =MAX(I24:AJ24) -> 1
B25: Chris | C25: SPG_Platform_Linux | D25: Compute Virtualization - Guest ROCm (virtio-gpu) | E25: ROCR-Runtime, ROCR-CLR development for virtio-gpu Pointer info refactor in ROCR for virtio driver agents Global memory APIs support for virtio driver agents Events APIs refactor for virtio driver agents Enable events wait API in ROCR virtio-gpu CLR adaptation for ROCR VIRTIO backend Host and guest Kernel developments for virtio-gpu Userptr feature in virtio-gpu mapped memory support back end virtio Upper level component virtualization support ROCm debugger for virtio-gpu ROCm tracer for virtio-gpu ROCm profiler for virtio-gpu HIP (runtime) for virtio-gpu | F25: China Shanghai | G25: alloc_MLS_Linux_3 | H25: Incremental - XCHG | R25: 1 | S25: 2 | T25: 2 | U25: 2 | V25: 2 | W25: 1 | X25: 1 | Y25: 0.5 | AK25: =SUM(I25:AJ25) -> 11.5 | AL25: =MAX(I25:AJ25) -> 2
B26: Chris | C26: SPG_Platform_Linux | D26: Compute Virtualization - Guest OpenCL (DOMU) | E26: ROCR Virtio Driver Adaptation for OpenCL2.0 (amdocl) Memory region and pool discovery for OpenCL Queue management adaptation Extend KfdVirtioDriver for OpenCL-specific allocation patterns (scratch, GWS, large buffers) Queue doorbell dispatch latency evaluation and optimization OpenCL Event and Signal Path HSA signal/event latency optimization under polling mode Events wait API integration with OpenCL callbacks and profiling OpenCL Feature Adaptation in DOMU Device capability correct reporting through virtio topology(bus-addressable, IPC, DMA-buf, etc.) DMA-buf / GL interop adaptation via virtio-gpu blob resources Image object support validation (tiling, format queries, read/write/copy paths) C11 atomics, device partitioning, device-side enqueue OCL 2.0 CTS tests debug | F26: China Shanghai | G26: alloc_MLS_Linux_3 | H26: Incremental - XCHG | R26: 1 | S26: 1 | T26: 2 | U26: 2 | V26: 2 | W26: 1 | X26: 1 | Y26: 0.5 | AK26: =SUM(I26:AJ26) -> 10.5 | AL26: =MAX(I26:AJ26) -> 2
B27: Chris | C27: SPG_Platform_Linux | D27: Compute Virtualization - Guest HIP & Mathlib & Tools (DOMU) | E27: Enable and validate ROCm user space HIP, math libraries, and tools on DOMU HIP Runtime, CLR Math libraries ROCblas/hipblas, rocFFT/hipFFT, rocRand, rocprim, rocSPARSE/hipSPARSE, MIOpen, rocSOLVER, hipSOLVER, hipBLASLlt, hipSPARSELt, hipRAND Tools ROCm Profiler, ROCm GDB, AMDSMI, ROCminfo | F27: China Shanghai | G27: alloc_MLS_Linux_3 | H27: Incremental - XCHG | R27: 0.5 | S27: 0.5 | T27: 1 | U27: 1 | V27: 1 | W27: 1 | X27: 0.5 | Y27: 0.5 | AK27: =SUM(I27:AJ27) -> 6 | AL27: =MAX(I27:AJ27) -> 1
B28: Chris | C28: SPG_Platform_Linux | D28: Compute Virtualization - Host KFD multiple context | E28: Linux Kernel KFD multiple contexts: Implement secondary kfd_process-es in kfd module Lifetime management of secondary kfd_process Refactoring sysfs entry for secondary kfd_process Identify secondary kfd_process by id and supportive functions. Support fence and evict for secondary kfd_process Support kfd_mmap for secondary kfd_process Support set_debug_trap ioctl for multiple contexts HIQ and DIQ improvements for multiple contexts Stretch goal (Linux KFD kernel): Upstreaming all the changes SVM support for secondary kfd_process UserPTR support for secondary kfd_process Libhsakmt (thunk) multiple context developments Primary context validation Secondary context support KFDtests for secondary context | F28: China Shanghai | G28: alloc_MLS_Linux_3 | H28: Incremental - XCHG | R28: 0.5 | S28: 1 | T28: 1 | U28: 1 | V28: 1 | W28: 1 | X28: 0.5 | Y28: 0.5 | AK28: =SUM(I28:AJ28) -> 6.5 | AL28: =MAX(I28:AJ28) -> 1
B29: Chris | C29: SPG_Platform_Linux | D29: VirtIO GPU emulation - Xen/QEMU/Virglrenderer DOM0 (Compute) | E29: Virglrenderer virtualized thunk developments for virtio-gpu Virglrenderer thunk API forwarding for virtio-gpu Multi KFD context feature modifications in virglrenderer QEMU, hypervisor development for virtio-gpu QEMU API forwarding features for HIP APIs Hypervisor, QEMU memory managements features for HIP APIs | F29: China Shanghai | G29: alloc_MLS_Linux_3 | H29: Incremental - XCHG | R29: 1 | S29: 1 | T29: 1.5 | U29: 1.5 | V29: 1.5 | W29: 1 | X29: 1 | Y29: 1 | AK29: =SUM(I29:AJ29) -> 9.5 | AL29: =MAX(I29:AJ29) -> 1.5
B30: Chris | C30: SPG_Platform_Linux | D30: DRM render node for ROCm virtualization | E30: DRM SVM for AMDGPU development which is required by latest unified KFD/KGD stack Initialization - Initialize drm_gpusvm during VM init IOCTL Interface - Add IOCTL to create SVM range and map system pages to VM Page Fault Handling - Retry page fault recovery by creating or finding SVM range and mapping pages Memory Invalidation - Implement amdgpu_svm_invalidate via MMU notifier to unmap SVM range and add to garbage collector Page Migration & Prefetch - Implement page migration with SVM range BO, drm_pagemap ops, amdgpu_migrate.c callbacks, prefetch IOCTL, and migration policy in fault handler based on preferred location Memory Eviction - Implement TTM eviction of SVM range BO to system memory under VRAM pressure using fence and evict worker Legacy Replacement - Optionally replace amdgpu_gem_userptr_ioctl with SVM IOCTL | F30: China Shanghai | G30: alloc_MLS_Linux_3 | H30: Incremental - XCHG | R30: 0.5 | S30: 0.5 | T30: 1 | U30: 1 | V30: 1 | W30: 1 | X30: 0.5 | Y30: 0.5 | AK30: =SUM(I30:AJ30) -> 6 | AL30: =MAX(I30:AJ30) -> 1
B31: Chris | C31: SPG_Platform_Linux | D31: Cross functional team support/ Integrated Delivery Support | E31: Providing debugging and feature support for other G&E software teams, including ATG, security, and display. | F31: China Shanghai | G31: alloc_MLS_Linux_3 | H31: Incremental - XCHG | R31: 1 | S31: 1 | T31: 2 | U31: 2 | V31: 2 | W31: 1 | X31: 1 | Y31: 1 | AK31: =SUM(I31:AJ31) -> 11 | AL31: =MAX(I31:AJ31) -> 2
B32: Chris | C32: SPG_Platform_Linux | D32: GPU recovery virtualization | E32: GPU recovery for virtio-gpu | F32: China Shanghai | G32: alloc_MLS_Linux_3 | H32: Incremental - XCHG | R32: 0 | S32: 0.5 | T32: 0.5 | U32: 1 | V32: 1 | W32: 1 | X32: 1 | Y32: 1 | AK32: =SUM(I32:AJ32) -> 6 | AL32: =MAX(I32:AJ32) -> 1
B33: Chris | C33: SPG_Platform_Linux | D33: Graphics Virtualization - Guest Android (Issue Debugging Support) | E33: Android VM DOMU Support (GFX issue debugging) Linux kernel (caladon_kernel) for virtio-gpu in Android VM Libdrm for virtio-gpu in Android VM Support other Android GLES graphics components (e.g., SurfaceFlinger/Skia) Support other Android Vulkan graphics components (e.g., SurfaceFlinger/Skia), for example, some components may migrate from OpenGL ES to Vulkan Android Angle support OpenGL ES CTS based on Angle. Support other GELS graphics components (e.g., SurfaceFlinger/Skia) based on Angle Display virtualization (like vMPO) for Android VM Gfxbench and regular 3D applications based on Vulkan and OpenGLES(Mesa RadeonSI & ANGLE) in Android VM | F33: China Shanghai | G33: alloc_MLS_Linux_3 | R33: 1 | S33: 1 | T33: 2 | U33: 3 | V33: 3 | W33: 3 | X33: 3 | Y33: 3 | AK33: =SUM(I33:AJ33) -> 19 | AL33: =MAX(I33:AJ33) -> 3
B34: Chris | C34: SPG_Platform_Linux | D34: Power Management Virtualization - Guest | E34: Linux DOMU S3/reboot support for suspend and resume | F34: China Shanghai | G34: alloc_MLS_Linux_3 | H34: Incremental - XCHG | R34: 0.5 | S34: 0.5 | T34: 1 | U34: 1 | V34: 1 | W34: 1 | X34: 0.5 | Y34: 0.5 | AK34: =SUM(I34:AJ34) -> 6 | AL34: =MAX(I34:AJ34) -> 1
B35: Chris | C35: SPG_Platform_Linux | D35: Linux - Solution Architect team | E35: Provide Linux virtualization solution architecture, technical alignment, and cross-component integration support. | F35: China Shanghai | G35: alloc_MLS_Linux_3 | H35: Incremental - XCHG | L35: 0.5 | M35: 0.5 | N35: 0.5 | O35: 0.5 | P35: 0.5 | Q35: 0.5 | R35: 0.5 | S35: 0.5 | T35: 0.5 | U35: 0.5 | V35: 0.5 | W35: 0.5 | X35: 0.5 | Y35: 0.5 | AK35: =SUM(I35:AJ35) -> 7 | AL35: =MAX(I35:AJ35) -> 0.5
B36: Chris | C36: SPG_Platform_Linux | D36: Linux IQE | E36: Validation support during bringup(silicon) - Feature Validation for ROCm/GFX/Xen/ML frameworks/tools/MM/Power/Display - Weekly integration Validation to maintain stable baseline - Full cycle test for each release | F36: China Shanghai | G36: alloc_MLS_Linux_1 | H36: Incremental - XCHG | S36: 2 | T36: 4 | U36: 5 | V36: 5 | W36: 4 | X36: 2 | Y36: 2 | AK36: =SUM(I36:AJ36) -> 24 | AL36: =MAX(I36:AJ36) -> 5
B37: Chris | C37: SPG_Platform_Linux | D37: AMD SMI | E37: AMD SMI support for Baremetal | F37: USA | G37: alloc_MLS_Linux_1 | H37: Incremental - XCHG | R37: 0.1 | S37: 0.2 | T37: 0.2 | U37: 0.1 | V37: 0.1 | W37: 0.1 | X37: 0.1 | Y37: 0.1 | AK37: =SUM(I37:AJ37) -> 1 | AL37: =MAX(I37:AJ37) -> 0.2
AK38: =SUM(I38:AJ38) -> 0 | AL38: =MAX(I38:AJ38) -> 0
AK39: =SUM(I39:AJ39) -> 0 | AL39: =MAX(I39:AJ39) -> 0
AK40: =SUM(I40:AJ40) -> 0 | AL40: =MAX(I40:AJ40) -> 0
AK41: =SUM(I41:AJ41) -> 0 | AL41: =MAX(I41:AJ41) -> 0
AK42: =SUM(I42:AJ42) -> 0 | AL42: =MAX(I42:AJ42) -> 0
...

Sheet Assumptions
A1: Instructions: Please enter your function's name and capture assumptions applicable to your sizing
A2: Team Name / Function | B2: Scope / Deliverables | C2: Assumptions | D2: Risks
A4: Bringup & Pre-Si Emulation (NPI) | B4: Linux Bringup & Pre-Si Emulation: - Pre-SI Emulation - Pre-SI Linux Bringup - Linux Bringup (Silicon) with Base kernel | D4: Clarifications : - What is the Board used for Capitola ? - Where is the bringup happens and any travel is needed ?
A5: Post Bringup(NTI) | B5: ROCm Support: - ROCm bringup on APU - ROCm Feats validation - KFD validation MM: - H264 and HEVC(Encode, Decode and Transcode) issue debug support. - NVE support BPI : 1. Build and Packaging 2. Separate Capitola branch creation. 3. Build script modifications if any. Graphics API : - Mesa, OpenGL 4.6, OpenGL ES 3.2, Vulkan-1.4 (Baremetal issue debug) Kernel support: - Kernel Consultation support Linux IQE - Feature validation for ROCm/GFX/Display/MM/tools/Xen/ML Frameworks with Linux OS - Weekly integration test - Full cycle release test | C5: ROCm Support: - Validate the ROCm FEATs like KFD test, rocr test, roc profiler, roc gdb, rocminfo, clinfo, rocmruntime, OCL, etc MM: - Debug support is limited to H.264 and HEVC use cases, including Encode, Decode, and Transcode only. - VCN5 does not support YUV422 Subsampling format. So we don’t support this. - No new feature development is included as part of this scope. - GStreamer-based development or support is explicitly out of scope. - QT framework is out of scope. Graphics : - OpenGL SC is deprecated and is explicitly out of scope. - There is no clarity from the program side on the VulkanSC requirement. No sizing has been done until we get the clarity. Kernel : - Kernel related consultation. Linux IQE -Validation scope for ROCm stack is limited to KFD test/rocr test/rocprofiler/rocgdb/OCL - ML framework scope limited to Pytorch, Ollama.cpp, llama.cpp, vllm, NO performance validation -FuSa related features are out of this sizing scope -RAS validation is out of scope | D5: - Does VulkanSC needs the GPU driver to be safety complaint ? - Any new work w.r.t VulkanSC needs rescoping. - No ASIL-B or ASIL-D efforts are estimated till we get the clear picture of usage on the UMD/D4KMD or ROCm side.
A6: Core Linux(Ray) | B6: Graphics Virtualization - Guest Linux GPU recovery virtualization VirtIO GPU emulation - Xen/QEMU/Virglrenderer DOM0 (Graphics) VirtIO GPU emulation - Xen/QEMU/Virglrenderer DOM0 (Graphics - Windows) Graphics Virtualization - Guest Windows UMD (Virgl) Display Virtualization Display Virtualization (Windows) Graphics Virtualization - Guest Windows KMD Compute Virtualization - Guest ROCm (virtio-gpu) Compute Virtualization - Guest OpenCL (DOMU) Compute Virtualization - Host KFD multiple context Compute Virtualization - Guest HIP & Mathlib & Tools (DOMU) VirtIO GPU emulation - Xen/QEMU/Virglrenderer DOM0 (Compute) Cross functional team support/ Integrated Delivery Support DRM render node for ROCm virtualization Power Management Virtualization - Guest Graphics Virtualization - Guest Android (Issue Debugging Support) Linux - Solution Architect team | C6: Linux: • Weston IVI is out of the scope. • Multidisplay is not scoped. • Dom0 and DomU should be in a display like Fairview Project. (One DOM0 + One DOMU in one single display). If requires more use cases, it need require CR. • Virtual primary plane is not scoped. • Functional safety (ASIL-B) for graphics driver and ROCm is not scoped. • P2P is not in scope. APU doesn’t support the P2P feature, so some IPC features cannot be enabled either. Windows: • Graphics Virtualization(UMD) → This phase provides a DirectX-10–based, GPU-accelerated Windows 10 desktop only. DX12, Windows 11, Vulkan, and Windows VM multimedia are explicitly out of scope. • No power management on Windows DOMU • Windows will not support vMPO/vPP, GPU timeout recovery.

Sheet Info

Sheet Pivot
A3: Cost ($M) | B3: HC Type
A4: Leader | B4: Existing - AOP | C4: Incremental - XCHG | D4: Grand Total
A5: Chris | B5: 1084977 | C5: 891263.8 | D5: 1976240.8
A6: Hugo | B6: 1242626.2 | D6: 1242626.2
A7: Matthias | C7: 210967.75 | D7: 210967.75
A8: Stephen | B8: 843870.99 | D8: 843870.99
A9: Grand Total | B9: 3171474.2 | C9: 1102231.5 | D9: 4273705.7

Sheet StatusTracking
B2: Team | C2: Contact | D2: Scope / Function / Impact / Involvement | E2: Status | F2: Comments

Sheet BrowserTab
A1: BROWSER VIEWING HAS BEEN DISABLED. PLEASE OPEN IN EXCEL DESKTOP APP TO USE THIS FILE. Click on the "Editing" button and select "Open in Desktop App"

Sheet Instructions
A1: Instructions
A3: Step | B3: Description | C3: Illustrations / Pictorials
A4: 1 | B4: In column D, look for your top-level teams in column D
A5: 2 | B5: In column E, type in your specific function or team name in column E, as needed (or leave blank)
A6: 3 | B6: In column G, select the HC type (Existing, FTE, Contractor) via drop down list. Do not mix existing and new HC together, use separate rows Add new rows as needed
A7: 4 | B7: In columns H through AA, fill in the HC estimate by quarter
A8: 5 | B8: Enter in scope deliverables, assumptions, risks in the Assumptions tab for your respective team(s)

Sheet LUT
B1: Look up Table for teams/leaders/category | F1: Lists for drop down menus | M1: CVP / Allocation Files drop down menus | V1: CVP / Top Level Teams drop down menus
B2: Top Level | C2: Leader | D2: Category | F2: Options | G2: HC Type | H2: Labour Rate | I2: Location | J2: Status | K2: Note | M2: CVP | N2: Rodney | O2: Chris | P2: Hugo | Q2: Matthias | R2: Stephen | S2: Syed | T2: Terry | U2: Jeffrey | V2: RodneyTeam | W2: ChrisTeam | X2: HugoTeam | Y2: MatthiasTeam | Z2: StephenTeam | AA2: SyedTeam | AB2: TerryTeam | AC2: JeffreyTeam
B3: 3D_Perf_Arch | C3: Rodney | D3: 3DGFX | F3: choice 1 | G3: Existing - AOP | H3: 57001.202 | I3: USA | M3: Chris | N3: alloc_CG 3D Drivers And Compilers | O3: {=_xlfn._xlws.SORT(_xlfn.UNIQUE(_xlfn._xlws.FILTER('[1]Active Alloc_Files'!$A$3:$A$100,'[1]Active Alloc_Files'!$H$3:$H$100=O2)),,1)} -> alloc_BTSR | P3: {=_xlfn._xlws.SORT(_xlfn.UNIQUE(_xlfn._xlws.FILTER('[1]Active Alloc_Files'!$A$3:$A$100,'[1]Active Alloc_Files'!$H$3:$H$100=P2)),,1)} -> alloc_Product Security | Q3: {=_xlfn._xlws.SORT(_xlfn.UNIQUE(_xlfn._xlws.FILTER('[1]Active Alloc_Files'!$A$3:$A$100,'[1]Active Alloc_Files'!$H$3:$H$100=Q2)),,1)} -> alloc_CE Markham | R3: {=_xlfn._xlws.SORT(_xlfn.UNIQUE(_xlfn._xlws.FILTER('[1]Active Alloc_Files'!$A$3:$A$100,'[1]Active Alloc_Files'!$H$3:$H$100=R2)),,1)} -> alloc_SQA Client APU | S3: {=_xlfn._xlws.SORT(_xlfn.UNIQUE(_xlfn._xlws.FILTER('[1]Active Alloc_Files'!$A$3:$A$100,'[1]Active Alloc_Files'!$H$3:$H$100=S2)),,1)} -> alloc_Display Solution_AlexS | T3: {=_xlfn._xlws.SORT(_xlfn.UNIQUE(_xlfn._xlws.FILTER('[1]Active Alloc_Files'!$A$3:$A$100,'[1]Active Alloc_Files'!$H$3:$H$100=T2)),,1)} -> alloc_ux | U3: {=_xlfn._xlws.SORT(_xlfn.UNIQUE(_xlfn._xlws.FILTER('[1]Active Alloc_Files'!$A$3:$A$100,'[1]Active Alloc_Files'!$H$3:$H$100=U2)),,1)} -> alloc_Software Technologies | V3: {=_xlfn._xlws.SORT(_xlfn.UNIQUE(_xlfn._xlws.FILTER([2]Directors!$B$2:$B$58,[2]Directors!$J$2:$J$58=N$2,"")),,1)} -> SPG_3D_ArchNPIPM | W3: {=_xlfn._xlws.SORT(_xlfn.UNIQUE(_xlfn._xlws.FILTER([2]Directors!$B$2:$B$58,[2]Directors!$J$2:$J$58=O$2,"")),,1)} -> SPG_ADV Technology | X3: {=_xlfn._xlws.SORT(_xlfn.UNIQUE(_xlfn._xlws.FILTER([2]Directors!$B$2:$B$58,[2]Directors!$J$2:$J$58=P$2,"")),,1)} -> SPG_Security | Y3: {=_xlfn._xlws.SORT(_xlfn.UNIQUE(_xlfn._xlws.FILTER([2]Directors!$B$2:$B$58,[2]Directors!$J$2:$J$58=Q$2,"")),,1)} -> SPG_CSE_FirstPartner_Customer Engineering | Z3: {=_xlfn._xlws.SORT(_xlfn.UNIQUE(_xlfn._xlws.FILTER([2]Directors!$B$2:$B$58,[2]Directors!$J$2:$J$58=R$2,"")),,1)} -> SPG_SSE Infrastructure | AA3: {=_xlfn._xlws.SORT(_xlfn.UNIQUE(_xlfn._xlws.FILTER([2]Directors!$B$2:$B$58,[2]Directors!$J$2:$J$58=S$2,"")),,1)} -> SPG_Display NPI | AB3: {=_xlfn._xlws.SORT(_xlfn.UNIQUE(_xlfn._xlws.FILTER([2]Directors!$B$2:$B$58,[2]Directors!$J$2:$J$58=T$2,"")),,1)} -> SPG_Roadmap Installer User Experience | AC3: {=_xlfn._xlws.SORT(_xlfn.UNIQUE(_xlfn._xlws.FILTER([2]Directors!$B$2:$B$58,[2]Directors!$J$2:$J$58=U$2,"")),,1)} -> SPG_SW Technology
B4: D3D | C4: Rodney | D4: 3DGFX | F4: choice 2 | G4: Incremental - XCHG | H4: 30452.764 | I4: Bulgaria | J4: Complete | K4: Sizing is CLOSED. This sheet is LOCKED and PROTECTED from editing. NO CHANGES are permitted while locked. Please contact Sam Huynh if you need to make any modifications. | M4: Hugo | O4: alloc_CG 3D Drivers and Compilers | Q4: alloc_CSE_CEPM | R4: alloc_SQA Core and Common Services | S4: alloc_Display Solution_CharlieW | V4: SPG_3D_CQE | W4: SPG_FWProgMgmt | Y4: SPG_CSE_FirstPartner_FAST | Z4: SPG_SSE QA | AA4: SPG_MM Audio
B5: HYD Graphics CQE | C5: Rodney | D5: 3DGFX | F5: choice 3 | H5: 30452.764 | I5: Greece | J5: In Progress | K5: Sizing is OPEN. Please UPDATE your estimates for your teams in this sheet. Also UPDATE the scope, assumptions and risks in the Assumptions tab. | M5: Jeffrey | O5: alloc_CP | Q5: alloc_CSE_CoreSW | R5: alloc_SQA CVSAI | S5: alloc_Display Solution_EricC | V5: SPG_3D_Perf_Arch | W5: SPG_Platform Security | Y5: SPG_Customer Eng | Z5: SPG_SSE RM | AA5: SPG_MM Video NPI
B6: Khronos3D | C6: Rodney | D6: 3DGFX | F6: choice 4 | H6: 30452.764 | I6: Brazil | J6: MS Project | K6: Sizing is EXTRACTED from MS Project Server and COPIED here. NO CHANGES are permitted on this sheet. Please update the resource allocation files and publish them, data will be updated daily. | M6: Matthias | O6: alloc_MLS_Linux_1 | Q6: alloc_CSE_CPMCN | R6: alloc_SQA GW dGPU | S6: alloc_Display Solution_JagM | V6: SPG_3D_PerfML | W6: SPG_Platform SW Arch | Y6: SPG_Mac Platform | AA6: SPG_MM Video NTI
B7: PAL | C7: Rodney | D7: 3DGFX | F7: choice 5 | H7: 30452.764 | I7: Mexico | M7: Rodney | O7: alloc_MLS_Linux_2 | Q7: alloc_CSE_CPMTW | R7: alloc_SQA Product Support and Enablement | S7: alloc_Display Solution_MazenS | V7: SPG_3D_Tooling | W7: SPG_Platform Virtualization | Y7: SPG_Operations | AA7: SPG_VPE & DisplayNTI
B8: Shader Compilers | C8: Rodney | D8: Shaders | F8: choice 6 | H8: 30452.764 | I8: Argentina | M8: Stephen | O8: alloc_MLS_Linux_3 | Q8: alloc_CSE_Management | R8: alloc_SQA Solutions | S8: alloc_Display Solution_MichaelV | V8: SPG_D3D | W8: SPG_Platform Windows | Y8: SPG_SW_ProgramManagers
B9: Shader Compilers – LLVM & SC | C9: Rodney | D9: Shaders | F9: choice 7 | H9: 30138.25 | I9: Canada | M9: Syed | O9: alloc_MLS_Linux_4 | Q9: alloc_CSE_Strategic | R9: alloc_SWInfra_IND | S9: alloc_Display Solution_NikolaC | V9: SPG_HYD Graphics CQE | W9: SPG_Platform_Linux
B10: SPG_3D_Perf_Arch | C10: Rodney | D10: 3DGFX | F10: choice 8 | H10: 12203.04 | I10: India Hyderabad | O10: alloc_OS_MUL_Security_Kernel_BLR | Q10: alloc_CSE_SWAE | R10: alloc_swinfra_na | S10: alloc_Display Solution_VladmirVelenta | V10: SPG_Khronos3D | W10: SPG_PMFW
B11: SPG_3D_Tooling | C11: Rodney | D11: 3DGFX | F11: choice 9 | H11: 30452.764 | I11: Australia | O11: alloc_PFO_PM_Arch | Q11: alloc_CSE_TL | R11: alloc_swrelman | S11: alloc_Display_MM_VP_Direct Reports | V11: SPG_Mac 3D | W11: SPG_SPIO
B12: SPG_D3D | C12: Rodney | D12: 3DGFX | F12: choice 10 | H12: 26138.97 | I12: Japan | O12: alloc_Platform SW Arch | Q12: alloc_PMO Common_BrianW | S12: alloc_Gaming_Engineering | V12: SPG_PAL | W12: SPG_VBIOS CP
B13: SPG_HYD Graphics CQE | C13: Rodney | D13: 3DGFX | H13: 24974.506 | I13: Taiwan | O13: alloc_PMFW | Q13: alloc_PMO Common_PaulM | S13: alloc_mmdrivers_video_encode | V13: SPG_ShaderCompiler | W13: SPG_VBIOS RLC
B14: SPG_Khronos3D | C14: Rodney | D14: 3DGFX | H14: 17893.502 | I14: Serbia | O14: alloc_PPL_ATG | Q14: alloc_PMO Common_SharmilyB | S14: alloc_mmdrivers_video_playback_pipelines | W14: SPG_VBIOS VBL
B15: SPG_Mac 3D | C15: Rodney | D15: 3DGFX | H15: 53696.445 | I15: France | O15: alloc_PPL_Virtualization | Q15: alloc_PMO Common_VithalP | S15: alloc_SWDEV_HYD_MM_Audio_NonWin
B16: SPG_PAL | C16: Rodney | D16: 3DGFX | H16: 35285.141 | I16: Germany | O16: alloc_PSPSecurity_MKM | Q16: alloc_Program Management_AlejandroR | S16: alloc_SWDEV_HYD_MM_Audio_Win
B17: SPG_Shader Compilers | C17: Rodney | D17: Shaders | H17: 41547.43 | I17: Italy | O17: alloc_RLC | Q17: alloc_Program Management_DerekY | S17: alloc_SWDEV_HYD_MM_Video
B18: SPG_ShaderCompiler | C18: Rodney | D18: Shaders | H18: 50477.43 | I18: Sweden | O18: alloc_SPIO | Q18: alloc_Program Management_JonB
B19: ADV Technology | C19: Chris | D19: ATG | H19: 55809.114 | I19: UK | O19: alloc_VBL | Q19: alloc_Program Management_ReyE
B20: IPU Driver - Existing | C20: Chris | D20: ATG | H20: 39047.15 | I20: Spain | O20: alloc_VPs_DirectReports | Q20: alloc_Program Management_StefanT
B21: IPU Validation | C21: Chris | D21: ATG | H21: 25848.236 | I21: Poland | O21: alloc_WSPG_BG_KMD_CORE | Q21: alloc_Program Management_SW Client and NOI
B22: Power/ Perf | C22: Chris | D22: ATG | H22: 27870.18 | I22: Netherlands | O22: alloc_WSPG_BG_KMD_Hyderabad | Q22: alloc_Program Management_VioF
B23: SPG_ADV Technology | C23: Chris | D23: ATG | H23: 12203.04 | I23: India Bangalore | O23: alloc_WSPG_BG_KMD_Solutions_CAN
B24: FWProgMgmt | C24: Chris | D24: PFO | H24: 27275.209 | I24: China Shanghai | O24: alloc_WSPG_BG_KMD_SRDC
B25: GFX-CP | C25: Chris | D25: PFO | H25: 27275.209 | I25: China Beijing and Shenzhen | O25: alloc_WSPG_BG_Leadership
B26: GFX-RLC | C26: Chris | D26: PFO | H26: 31000 | I26: Global | O26: alloc_WSPG_BG_System and Power
B27: PMFW | C27: Chris | D27: PFO | O27: alloc_WSPG_BG_Test and Tools
B28: SMU | C28: Chris | D28: PFO | O28: alloc_WSPG_MsftInterface
B29: SPG_Architecture and Sys IP | C29: Chris | D29: PFO | O29: alloc_WSPG_PM_TL
B30: SPG_FWProgMgmt | C30: Chris | D30: PFO | O30: alloc_WSPG_QE_Core
B31: SPG_GFX-CP | C31: Chris | D31: PFO | O31: alloc_WSPG_QE_HYD
B32: SPG_GFX-RLC | C32: Chris | D32: PFO | O32: alloc_WSPG_QE_MKM
B33: SPG_IPU Driver - Existing | C33: Chris | D33: PFO | O33: alloc_WSPG_QE_SRDC
B34: SPG_IPU Validation | C34: Chris | D34: PFO | O34: alloc_WSPG_QE_Stability_NTI
B35: SPG_PMFW | C35: Chris | D35: PFO | O35: alloc_WSPG_QE_TnD_NOI
B36: SPG_SMU | C36: Chris | D36: PFO
B37: SPG_SPIO | C37: Chris | D37: PFO
B38: SPG_VBIOS | C38: Chris | D38: PFO
B39: SPG_VBIOS CP | C39: Chris | D39: PFO
B40: SPG_VBIOS RLC | C40: Chris | D40: PFO
...

Sheet Ramp Scenarios
B2: Scenarios | C2: Cost Factor | D2: M1 | E2: M2 | F2: M3 | G2: Ramp Curve
B3: NC - No change | C3: =((D3/100)+(E3/100)+(F3/100))/3 -> 1 | D3: 100 | E3: 100 | F3: 100
B4: 0.9 | C4: =((D4/100)+(E4/100)+(F4/100))/3 -> 0.9 | D4: 90 | E4: 90 | F4: 90
B5: 0.8 | C5: =((D5/100)+(E5/100)+(F5/100))/3 -> 0.8 | D5: 80 | E5: 80 | F5: 80
B6: 0.7 | C6: =((D6/100)+(E6/100)+(F6/100))/3 -> 0.7 | D6: 70 | E6: 70 | F6: 70
B7: 0.6 | C7: =((D7/100)+(E7/100)+(F7/100))/3 -> 0.6 | D7: 60 | E7: 60 | F7: 60
B8: 0.5 | C8: =((D8/100)+(E8/100)+(F8/100))/3 -> 0.5 | D8: 50 | E8: 50 | F8: 50
B9: 0.4 | C9: =((D9/100)+(E9/100)+(F9/100))/3 -> 0.4 | D9: 40 | E9: 40 | F9: 40
B10: 0.2 | C10: =((D10/100)+(E10/100)+(F10/100))/3 -> 0.2 | D10: 20 | E10: 20 | F10: 20
B11: OMIT - remove | C11: 0 | D11: 0 | E11: 0 | F11: 0
